Workbook

Sheet Cover
C6: GardenCore LLC
C8: Carve-out of Oldcastle Lawn & Garden, Inc. from CRH plc
C9: Leveraged buyout by Pacific Avenue Capital Partners (Fund II) | $1.1bn enterprise value
C11: Sources & Uses, Debt Waterfall and Returns Model
C14: Legend
C15: 1,100.0 | D15: Hardcoded input
C16: 4.0% | D16: Key forecast assumption (change these to run cases)
C17: 1,148.1 | D17: Formula
C18: 153.4 | D18: Link from another sheet
C19: Section header | D19: Section header
C22: Contents
C23: Transaction | D23: Deal facts, key assumptions, financing structure, sources & uses
C24: Operating Model | D24: Revenue, EBITDAR, sale-leaseback rent, EBITDA and cash flow, Years 1-5
C25: Debt Waterfall | D25: Cash available for debt service, ABL revolver, term loan, cash sweep, credit stats
C26: Returns | D26: Exit, IRR / MOIC, break-even multiples, sensitivities, LP / GP distribution waterfall
C29: Name | D29: Rowan Das
C30: Date | D30: 46306
C31: Email | D31: rowanamlan@gmail.com
C33: Disclosed: $1.1bn enterprise value, $400mm W. P. Carey sale-leaseback, advisors and fund. Not disclosed: GardenCore's revenue,
C34: EBITDA and debt terms. Those inputs are assumptions (blue) and should be updated if better data becomes available.

Sheet Transaction
C2: GardenCore LLC: Transaction Summary
C3: ($ in millions, unless noted)
C5: Transaction Overview | H5: Source
C6: Target | D6: Oldcastle Lawn & Garden, Inc. (GardenCore LLC after close) | H6: Pacific Avenue press release, 30-Apr-2026
C7: Seller | D7: CRH plc (NYSE: CRH), through Oldcastle APG | H7: The Deal, 1-May-2026
C8: Buyer | D8: Pacific Avenue Capital Partners, via Pacific Avenue Fund II | H8: Pacific Avenue press release; deal notes
C9: Timing | D9: Announced 30-Apr-2026; closed early May 2026 | H9: Press release; W. P. Carey 8-K (sale-leaseback closed 8-May-2026)
C10: Business | D10: Mulch, soil, stone and lime; private label and branded programs | H10: Pacific Avenue press release
C11: Footprint | D11: 1,400+ employees; 55+ U.S. manufacturing facilities | H11: Pacific Avenue press release
C12: Buy-side advisors | D12: Jefferies (financial), Weil (legal), Sidley (debt financing) | H12: Press release; Sidley announcement, 13-May-2026
C13: Sell-side advisors | D13: BofA Securities (financial), Kilpatrick Townsend (legal) | H13: Press release; The Deal
C14: Sale-leaseback | D14: W. P. Carey: $400mm, 43 plants, 24 states, 20-yr triple-net lease | H14: W. P. Carey Q2-2026 earnings call; 8-K (May-2026)
C15: Fund | D15: Pacific Avenue Fund II: $1.65bn+ committed, closed Aug-2025 | H15: Business Wire, 12-Aug-2025
C16: Debt package | D16: Not disclosed; modeled as ABL revolver + first lien term loan | H16: Assumption
C18: Key Transaction Assumptions | D18: Value | H18: Basis / source
C20: Close date | D20: 46150 | H20: W. P. Carey 8-K: sale-leaseback closed in conjunction with the acquisition
C21: Purchase enterprise value | D21: 1100 | H21: Disclosed ($1.1bn)
C22: LTM revenue at close | D22: 720 | H22: Assumed: not disclosed (~$0.5mm per employee x 1,400+ employees)
C23: LTM EBITDAR margin (before sale-leaseback rent) | D23: 0.175 | H23: Assumed: not disclosed
C24: LTM EBITDAR | D24: =D22*D23 -> 126
C25: Implied EV / LTM EBITDAR | D25: =D21/D24 -> 8.7301587 | H25: Purchase multiple on the business before the sale-leaseback
C26: Sale-leaseback proceeds (W. P. Carey) | D26: 400 | H26: Disclosed: W. P. Carey Q2-2026 earnings call
C27: Sale-leaseback cap rate | D27: 0.074 | H27: Assumed at W. P. Carey's 2026 YTD avg. initial cash cap rate (7.4%)
C28: Annual rent escalator | D28: 0.02 | H28: Assumed: disclosed only as 'fixed annual rent increases'
C29: Year-1 rent | D29: =D26*D27 -> 29.6
C30: PF LTM EBITDA (after rent) | D30: =D24-D29 -> 96.4 | H30: What lenders underwrite once the plants are leased back
C31: Net purchase price after sale-leaseback | D31: =D21-D26 -> 700
C32: Net price / PF EBITDA | D32: =D31/D30 -> 7.2614108 | H32: Effective entry multiple funded by debt + equity
C33: Advisory & transaction fees (% of EV) | D33: 0.02 | H33: Assumed: Jefferies, Weil, Sidley and other deal costs
C34: Minimum cash balance | D34: 15 | H34: Assumed
C35: Tax rate | D35: 0.25 | H35: Assumed: U.S. federal (21%) + state
C36: Pacific Avenue Fund II committed capital | D36: 1650 | H36: Business Wire, 12-Aug-2025 ($1.65bn+, incl. EU sidecar)
C38: Financing Structure (Assumed: debt terms not disclosed)
C39: Facility | D39: Commitment | E39: At close | F39: Pricing | G39: Fees / OID | H39: Notes
C40: ABL revolving credit facility | D40: 175 | E40: 75 | F40: ="SOFR + "&TEXT('Debt Waterfall'!G33,"0.00%") -> SOFR + 1.75% | G40: 0.01 | H40: Funds seasonal inventory build; secured by receivables and inventory; 5-yr; 0.375% undrawn fee
C41: First lien term loan (private credit) | D41: 375 | E41: =D41 -> 375 | F41: ="SOFR + "&TEXT('Debt Waterfall'!G53,"0.00%") -> SOFR + 5.25% | G41: 0.025 | H41: Unitranche-style; 0.75% SOFR floor; 1% annual amortization; 7-yr; 75% excess cash sweep
C42: Sale-leaseback (W. P. Carey) | D42: =D26 -> 400 | E42: =D26 -> 400 | F42: =TEXT(D27,"0.0%")&" cap rate" -> 7.4% cap rate | H42: Monetizes all 43 owned plants; not debt, but rent becomes a fixed charge ahead of equity
C44: Sources & Uses
C45: Sources | D45: $mm | E45: % of total | F45: x PF EBITDA
C46: ABL revolver (drawn at close) | D46: =E40 -> 75 | E46: =D46/D$50 -> 0.065323898 | F46: =D46/$D$30 -> 0.7780083
...

Sheet Operating Model
C2: GardenCore LLC: Operating Model
C3: ($ in millions) | E3: Period | F3: PF Close | G3: Year 1 | H3: Year 2 | I3: Year 3 | J3: Year 4 | K3: Year 5
E4: Fiscal start | G4: =F5 -> 46150 | H4: =G5+1 -> 46515 | I4: =H5+1 -> 46881 | J4: =I5+1 -> 47246 | K4: =J5+1 -> 47611
E5: Fiscal end | F5: =Transaction!$D$20 -> 46150 | G5: =EDATE(G4,12)-1 -> 46514 | H5: =EDATE(H4,12)-1 -> 46880 | I5: =EDATE(I4,12)-1 -> 47245 | J5: =EDATE(J4,12)-1 -> 47610 | K5: =EDATE(K4,12)-1 -> 47975
E6: Days | G6: =G5-G4+1 -> 365 | H6: =H5-H4+1 -> 366 | I6: =I5-I4+1 -> 365 | J6: =J5-J4+1 -> 365 | K6: =K5-K4+1 -> 365
C8: Income Statement
C9: Revenue | F9: =Transaction!$D$22 -> 720 | G9: =F9*(1+G10) -> 748.8 | H9: =G9*(1+H10) -> 782.496 | I9: =H9*(1+I10) -> 821.6208 | J9: =I9*(1+J10) -> 862.70184 | K9: =J9*(1+K10) -> 905.83693
C10: Revenue growth | G10: 0.04 | H10: 0.045 | I10: 0.05 | J10: 0.05 | K10: 0.05
C11: EBITDAR margin | F11: =Transaction!$D$23 -> 0.175 | G11: 0.1775 | H11: 0.1825 | I11: 0.1875 | J11: 0.1925 | K11: 0.195
C12: EBITDAR | F12: =F9*F11 -> 126 | G12: =G9*G11 -> 132.912 | H12: =H9*H11 -> 142.80552 | I12: =I9*I11 -> 154.0539 | J12: =J9*J11 -> 166.0701 | K12: =K9*K11 -> 176.6382
C13: (-) Rent: W. P. Carey sale-leaseback | F13: =-Transaction!$D$29 -> -29.6 | G13: =-Transaction!$D$29 -> -29.6 | H13: =G13*(1+Transaction!$D$28) -> -30.192 | I13: =H13*(1+Transaction!$D$28) -> -30.79584 | J13: =I13*(1+Transaction!$D$28) -> -31.411757 | K13: =J13*(1+Transaction!$D$28) -> -32.039992
C14: EBITDA (after rent) | F14: =F12+F13 -> 96.4 | G14: =G12+G13 -> 103.312 | H14: =H12+H13 -> 112.61352 | I14: =I12+I13 -> 123.25806 | J14: =J12+J13 -> 134.65835 | K14: =K12+K13 -> 144.59821
C15: EBITDA margin | F15: =F14/F9 -> 0.13388889 | G15: =G14/G9 -> 0.13797009 | H15: =H14/H9 -> 0.14391578 | I15: =I14/I9 -> 0.15001818 | J15: =J14/J9 -> 0.15608909 | K15: =K14/K9 -> 0.1596294
C16: (-) Separation & standalone costs (one-time) | G16: -12 | H16: -5 | I16: 0 | J16: 0 | K16: 0
C17: (-) Depreciation & amortization | G17: =-G9*G18 -> -18.72 | H17: =-H9*H18 -> -19.5624 | I17: =-I9*I18 -> -20.54052 | J17: =-J9*J18 -> -21.567546 | K17: =-K9*K18 -> -22.645923
C18: D&A % of revenue | G18: 0.025 | H18: 0.025 | I18: 0.025 | J18: 0.025 | K18: 0.025
C19: EBIT | G19: =G14+G16+G17 -> 72.592 | H19: =H14+H16+H17 -> 88.05112 | I19: =I14+I16+I17 -> 102.71754 | J19: =J14+J16+J17 -> 113.0908 | K19: =K14+K16+K17 -> 121.95229
C20: (-) Interest expense & fees | G20: ='Debt Waterfall'!G17 -> -38.330323 | H20: ='Debt Waterfall'!H17 -> -35.869861 | I20: ='Debt Waterfall'!I17 -> -33.033392 | J20: ='Debt Waterfall'!J17 -> -29.862009 | K20: ='Debt Waterfall'!K17 -> -25.360133
C21: Pre-tax income | G21: =G19+G20 -> 34.261677 | H21: =H19+H20 -> 52.181259 | I21: =I19+I20 -> 69.684148 | J21: =J19+J20 -> 83.228793 | K21: =K19+K20 -> 96.592153
C22: (-) Taxes | G22: =-MAX(0,G21*Transaction!$D$35) -> -8.5654193 | H22: =-MAX(0,H21*Transaction!$D$35) -> -13.045315 | I22: =-MAX(0,I21*Transaction!$D$35) -> -17.421037 | J22: =-MAX(0,J21*Transaction!$D$35) -> -20.807198 | K22: =-MAX(0,K21*Transaction!$D$35) -> -24.148038
C23: Net income | G23: =G21+G22 -> 25.696258 | H23: =H21+H22 -> 39.135944 | I23: =I21+I22 -> 52.263111 | J23: =J21+J22 -> 62.421595 | K23: =K21+K22 -> 72.444115
C25: Cash Flow Before Debt Service
C26: EBITDA (after rent) | G26: =G14 -> 103.312 | H26: =H14 -> 112.61352 | I26: =I14 -> 123.25806 | J26: =J14 -> 134.65835 | K26: =K14 -> 144.59821
C27: (-) Separation & standalone costs | G27: =G16 -> -12 | H27: =H16 -> -5 | I27: =I16 -> 0 | J27: =J16 -> 0 | K27: =K16 -> 0
C28: (-) Cash taxes | G28: =G22 -> -8.5654193 | H28: =H22 -> -13.045315 | I28: =I22 -> -17.421037 | J28: =J22 -> -20.807198 | K28: =K22 -> -24.148038
C29: Net working capital balance | F29: =F9*F30 -> 100.8 | G29: =G9*G30 -> 104.832 | H29: =H9*H30 -> 109.54944 | I29: =I9*I30 -> 115.02691 | J29: =J9*J30 -> 120.77826 | K29: =K9*K30 -> 126.81717
C30: NWC % of revenue | F30: 0.14 | G30: 0.14 | H30: 0.14 | I30: 0.14 | J30: 0.14 | K30: 0.14
C31: (-) Increase in net working capital | G31: =-(G29-F29) -> -4.032 | H31: =-(H29-G29) -> -4.71744 | I31: =-(I29-H29) -> -5.477472 | J31: =-(J29-I29) -> -5.7513456 | K31: =-(K29-J29) -> -6.0389129
C32: Cash flow from operations (before interest) | G32: =G26+G27+G28+G31 -> 78.714581 | H32: =H26+H27+H28+H31 -> 89.850765 | I32: =I26+I27+I28+I31 -> 100.35955 | J32: =J26+J27+J28+J31 -> 108.0998 | K32: =K26+K27+K28+K31 -> 114.41126
C33: (-) Capital expenditures | G33: =-G9*G34 -> -20.592 | H33: =-H9*H34 -> -21.51864 | I33: =-I9*I34 -> -22.594572 | J33: =-J9*J34 -> -23.724301 | K33: =-K9*K34 -> -24.910516
C34: Capex % of revenue | G34: 0.0275 | H34: 0.0275 | I34: 0.0275 | J34: 0.0275 | K34: 0.0275
C35: Cash flow from investing | G35: =G33 -> -20.592 | H35: =H33 -> -21.51864 | I35: =I33 -> -22.594572 | J35: =J33 -> -23.724301 | K35: =K33 -> -24.910516
C36: Free cash flow before debt service | G36: =G32+G35 -> 58.122581 | H36: =H32+H35 -> 68.332125 | I36: =I32+I35 -> 77.764979 | J36: =J32+J35 -> 84.375503 | K36: =K32+K35 -> 89.500743
C37: Levered free cash flow (after interest) | G37: =G36+G20 -> 19.792258 | H37: =H36+H20 -> 32.462264 | I37: =I36+I20 -> 44.731587 | J37: =J36+J20 -> 54.513494 | K37: =K36+K20 -> 64.14061

Sheet Debt Waterfall
C2: GardenCore LLC: Debt Waterfall
C3: ($ in millions) | E3: Period | F3: ='Operating Model'!F3 -> PF Close | G3: ='Operating Model'!G3 -> Year 1 | H3: ='Operating Model'!H3 -> Year 2 | I3: ='Operating Model'!I3 -> Year 3 | J3: ='Operating Model'!J3 -> Year 4 | K3: ='Operating Model'!K3 -> Year 5
E4: Fiscal start | G4: ='Operating Model'!G4 -> 46150 | H4: ='Operating Model'!H4 -> 46515 | I4: ='Operating Model'!I4 -> 46881 | J4: ='Operating Model'!J4 -> 47246 | K4: ='Operating Model'!K4 -> 47611
C5: Close date: | D5: =Transaction!D20 -> 46150 | E5: Fiscal end | F5: ='Operating Model'!F5 -> 46150 | G5: ='Operating Model'!G5 -> 46514 | H5: ='Operating Model'!H5 -> 46880 | I5: ='Operating Model'!I5 -> 47245 | J5: ='Operating Model'!J5 -> 47610 | K5: ='Operating Model'!K5 -> 47975
C6: Circuit breaker (On = interest on opening balance) | D6: Off | E6: Days | G6: ='Operating Model'!G6 -> 365 | H6: ='Operating Model'!H6 -> 366 | I6: ='Operating Model'!I6 -> 365 | J6: ='Operating Model'!J6 -> 365 | K6: ='Operating Model'!K6 -> 365
C9: Cash Liquidity
C11: Cash, beginning of period | G11: =F65 -> 15 | H11: =G65 -> 15 | I11: =H65 -> 15 | J11: =I65 -> 17.684027 | K11: =J65 -> 28.36188
C12: (+) Cash flow from operations (before interest) | G12: ='Operating Model'!G32 -> 78.714581 | H12: ='Operating Model'!H32 -> 89.850765 | I12: ='Operating Model'!I32 -> 100.35955 | J12: ='Operating Model'!J32 -> 108.0998 | K12: ='Operating Model'!K32 -> 114.41126
C13: (+) Cash flow from investing | G13: ='Operating Model'!G35 -> -20.592 | H13: ='Operating Model'!H35 -> -21.51864 | I13: ='Operating Model'!I35 -> -22.594572 | J13: ='Operating Model'!J35 -> -23.724301 | K13: ='Operating Model'!K35 -> -24.910516
C14: (-) Minimum cash balance | G14: =-Transaction!$D$34 -> -15 | H14: =-Transaction!$D$34 -> -15 | I14: =-Transaction!$D$34 -> -15 | J14: =-Transaction!$D$34 -> -15 | K14: =-Transaction!$D$34 -> -15
C15: Cash available for debt service | G15: =SUM(G11:G14) -> 58.122581 | H15: =SUM(H11:H14) -> 68.332125 | I15: =SUM(I11:I14) -> 77.764979 | J15: =SUM(J11:J14) -> 87.05953 | K15: =SUM(K11:K14) -> 102.86262
C17: (-) Interest expense & fees (all facilities) | G17: =-(G37+G38+G58) -> -38.330323 | H17: =-(H37+H38+H58) -> -35.869861 | I17: =-(I37+I38+I58) -> -33.033392 | J17: =-(J37+J38+J58) -> -29.862009 | K17: =-(K37+K38+K58) -> -25.360133
C18: (-) Mandatory amortization | G18: =G47 -> -3.75 | H18: =H47 -> -3.75 | I18: =I47 -> -3.75 | J18: =J47 -> -3.75 | K18: =K47 -> -3.75
C19: Cash available after interest & mandatory repayment | G19: =G15+G17+G18 -> 16.042258 | H19: =H15+H17+H18 -> 28.712264 | I19: =I15+I17+I18 -> 40.981587 | J19: =J15+J17+J18 -> 53.447522 | K19: =K15+K17+K18 -> 73.75249
C21: Revolving Credit Facility
C22: ="ABL revolver: $"&TEXT(Transaction!D40,"0")&"mm commitment, SOFR + "&TEXT(G33,"0.00%")&", undrawn fee "&TEXT(G35,"0.000%")&", 5-year" -> ABL revolver: $175mm commitment, SOFR + 1.75%, undrawn fee 0.375%, 5-year
C24: Commitment | F24: =Transaction!$D$40 -> 175 | G24: =F24 -> 175 | H24: =G24 -> 175 | I24: =H24 -> 175 | J24: =I24 -> 175 | K24: =J24 -> 175
C26: Principal Balance
C27: Opening | G27: =F29 -> 75 | H27: =G29 -> 58.957742 | I27: =H29 -> 30.245478 | J27: =I29 -> 0 | K27: =J29 -> 0
C28: (+) Draw / (-) repayment | G28: =IF(G19<0,MIN(-G19,G24-G27),-MIN(G27,G19)) -> -16.042258 | H28: =IF(H19<0,MIN(-H19,H24-H27),-MIN(H27,H19)) -> -28.712264 | I28: =IF(I19<0,MIN(-I19,I24-I27),-MIN(I27,I19)) -> -30.245478 | J28: =IF(J19<0,MIN(-J19,J24-J27),-MIN(J27,J19)) -> 0 | K28: =IF(K19<0,MIN(-K19,K24-K27),-MIN(K27,K19)) -> 0
C29: Closing | F29: =Transaction!$E$40 -> 75 | G29: =G27+G28 -> 58.957742 | H29: =H27+H28 -> 30.245478 | I29: =I27+I28 -> 0 | J29: =J27+J28 -> 0 | K29: =K27+K28 -> 0
C30: Available capacity | F30: =F24-F29 -> 100 | G30: =G24-G29 -> 116.04226 | H30: =H24-H29 -> 144.75452 | I30: =I24-I29 -> 175 | J30: =J24-J29 -> 175 | K30: =K24-K29 -> 175
C32: Benchmark rate (SOFR) | G32: 0.039 | H32: 0.0365 | I32: 0.035 | J32: 0.035 | K32: 0.035
C33: Spread | G33: 0.0175 | H33: =G33 -> 0.0175 | I33: =H33 -> 0.0175 | J33: =I33 -> 0.0175 | K33: =J33 -> 0.0175
C34: Interest rate | G34: =G32+G33 -> 0.0565 | H34: =H32+H33 -> 0.054 | I34: =I32+I33 -> 0.0525 | J34: =J32+J33 -> 0.0525 | K34: =K32+K33 -> 0.0525
C35: Undrawn commitment fee | G35: 0.00375 | H35: =G35 -> 0.00375 | I35: =H35 -> 0.00375 | J35: =I35 -> 0.00375 | K35: =J35 -> 0.00375
C37: Interest expense | G37: =IF($D$6="On",G27,AVERAGE(G27,G29))*G34*G$6/365 -> 3.7843062 | H37: =IF($D$6="On",H27,AVERAGE(H27,H29))*H34*H$6/365 -> 2.4150855 | I37: =IF($D$6="On",I27,AVERAGE(I27,I29))*I34*I$6/365 -> 0.7939438 | J37: =IF($D$6="On",J27,AVERAGE(J27,J29))*J34*J$6/365 -> 0 | K37: =IF($D$6="On",K27,AVERAGE(K27,K29))*K34*K$6/365 -> 0
C38: Undrawn commitment fee | G38: =(G24-IF($D$6="On",G27,AVERAGE(G27,G29)))*G35*G$6/365 -> 0.40507923 | H38: =(H24-IF($D$6="On",H27,AVERAGE(H27,H29)))*H35*H$6/365 -> 0.49033367 | I38: =(I24-IF($D$6="On",I27,AVERAGE(I27,I29)))*I35*I$6/365 -> 0.59953973 | J38: =(J24-IF($D$6="On",J27,AVERAGE(J27,J29)))*J35*J$6/365 -> 0.65625 | K38: =(K24-IF($D$6="On",K27,AVERAGE(K27,K29)))*K35*K$6/365 -> 0.65625
C40: Cash available post-revolver | G40: =G19+G28 -> 0 | H40: =H19+H28 -> 0 | I40: =I19+I28 -> 10.736109 | J40: =J19+J28 -> 53.447522 | K40: =K19+K28 -> 73.75249
C42: Term Loans
C43: ="First lien term loan (private credit): $"&TEXT(Transaction!D41,"0")&"mm, SOFR + "&TEXT(G53,"0.00%")&" ("&TEXT(G52,"0.00%")&" floor), "&TEXT(G55,"0%")&" amortization, 7-year" -> First lien term loan (private credit): $375mm, SOFR + 5.25% (0.75% floor), 1% amortization, 7-year
C45: Principal Balance
C46: Opening | G46: =F49 -> 375 | H46: =G49 -> 371.25 | I46: =H49 -> 367.5 | J46: =I49 -> 355.69792 | K46: =J49 -> 311.86228
C47: (-) Mandatory amortization | G47: =-MIN(G46,$F$49*G55) -> -3.75 | H47: =-MIN(H46,$F$49*H55) -> -3.75 | I47: =-MIN(I46,$F$49*I55) -> -3.75 | J47: =-MIN(J46,$F$49*J55) -> -3.75 | K47: =-MIN(K46,$F$49*K55) -> -3.75
C48: (-) Optional prepayment (excess cash sweep) | G48: =-MIN(G46+G47,MAX(0,G40)*G56) -> 0 | H48: =-MIN(H46+H47,MAX(0,H40)*H56) -> 0 | I48: =-MIN(I46+I47,MAX(0,I40)*I56) -> -8.0520815 | J48: =-MIN(J46+J47,MAX(0,J40)*J56) -> -40.085641 | K48: =-MIN(K46+K47,MAX(0,K40)*K56) -> -55.314368
C49: Closing | F49: =Transaction!$E$41 -> 375 | G49: =G46+G47+G48 -> 371.25 | H49: =H46+H47+H48 -> 367.5 | I49: =I46+I47+I48 -> 355.69792 | J49: =J46+J47+J48 -> 311.86228 | K49: =K46+K47+K48 -> 252.79791
C51: Benchmark rate (SOFR) | G51: =G32 -> 0.039 | H51: =H32 -> 0.0365 | I51: =I32 -> 0.035 | J51: =J32 -> 0.035 | K51: =K32 -> 0.035
C52: SOFR floor | G52: 0.0075 | H52: =G52 -> 0.0075 | I52: =H52 -> 0.0075 | J52: =I52 -> 0.0075 | K52: =J52 -> 0.0075
C53: Spread | G53: 0.0525 | H53: =G53 -> 0.0525 | I53: =H53 -> 0.0525 | J53: =I53 -> 0.0525 | K53: =J53 -> 0.0525
C54: Interest rate | G54: =MAX(G51,G52)+G53 -> 0.0915 | H54: =MAX(H51,H52)+H53 -> 0.089 | I54: =MAX(I51,I52)+I53 -> 0.0875 | J54: =MAX(J51,J52)+J53 -> 0.0875 | K54: =MAX(K51,K52)+K53 -> 0.0875
...

Sheet Returns
C2: GardenCore LLC: Returns Analysis
C3: ($ in millions)
C5: Exit Assumptions
C6: Exit year (1-5) | D6: 5
C7: Exit multiple (EV / EBITDA after rent) | D7: 7.25 | J7: Base case exits at roughly the entry multiple (no multiple expansion)
C8: Entry multiple (net price / PF EBITDA), for reference | D8: =Transaction!D32 -> 7.2614108
C9: Exit transaction costs (% of EV) | D9: 0.015
C11: Sponsor Returns
C12: Exit EBITDA (after rent) | D12: =INDEX('Operating Model'!$G$14:$K$14,$D$6) -> 144.59821
C13: Exit enterprise value | D13: =D7*D12 -> 1048.337
C14: (-) Exit transaction costs | D14: =-D13*D9 -> -15.725055
C15: (-) Total debt at exit | D15: =-INDEX('Debt Waterfall'!$G$69:$K$69,$D$6) -> -252.79791
C16: (+) Cash at exit | D16: =INDEX('Debt Waterfall'!$G$65:$K$65,$D$6) -> 33.438123
C17: Equity value at exit | D17: =SUM(D13:D16) -> 813.25218
C18: Sponsor equity invested | D18: =Transaction!D49 -> 298.125
C19: MOIC | D19: =D17/D18 -> 2.7278899
C20: IRR | D20: =IF(D17>0,(D17/D18)^(1/D6)-1,-1) -> 0.22226498
C22: Sponsor cash flows | D22: 0 | E22: 1 | F22: 2 | G22: 3 | H22: 4 | I22: 5
C23: Equity (invested) / returned | D23: =-D18 -> -298.125 | E23: =IF(E$22=$D$6,$D$17,0) -> 0 | F23: =IF(F$22=$D$6,$D$17,0) -> 0 | G23: =IF(G$22=$D$6,$D$17,0) -> 0 | H23: =IF(H$22=$D$6,$D$17,0) -> 0 | I23: =IF(I$22=$D$6,$D$17,0) -> 813.25218
C24: IRR check (Excel IRR on cash flows) | D24: =IRR(D23:I23) -> 0.22226498
C26: Break-even Analysis: Exit Multiple Needed for Each Return Level
C27: Target gross IRR | D27: Exit equity needed | E27: Exit EV needed | F27: Exit multiple needed | G27: Cushion vs. base (turns) | J27: What it means
C28: 0 | D28: =$D$18*(1+C28)^$D$6 -> 298.125 | E28: =(D28-$D$15-$D$16)/(1-$D$9) -> 525.36527 | F28: =E28/$D$12 -> 3.6332764 | G28: =$D$7-F28 -> 3.6167236 | J28: Capital returned: below this, the fund loses money on the deal
C29: 0.08 | D29: =$D$18*(1+C29)^$D$6 -> 438.04343 | E29: =(D29-$D$15-$D$16)/(1-$D$9) -> 667.41444 | F29: =E29/$D$12 -> 4.615648 | G29: =$D$7-F29 -> 2.634352 | J29: LPs' preferred return (typical 8% hurdle); below this, no carry for the GP
C30: 0.15 | D30: =$D$18*(1+C30)^$D$6 -> 599.63586 | E30: =(D30-$D$15-$D$16)/(1-$D$9) -> 831.46766 | F30: =E30/$D$12 -> 5.7501933 | G30: =$D$7-F30 -> 1.4998067 | J30: Low end of a typical buyout target
C31: 0.2 | D31: =$D$18*(1+C31)^$D$6 -> 741.8304 | E31: =(D31-$D$15-$D$16)/(1-$D$9) -> 975.8276 | F31: =E31/$D$12 -> 6.7485455 | G31: =$D$7-F31 -> 0.50145448 | J31: Typical buyout target
C32: 0.25 | D32: =$D$18*(1+C32)^$D$6 -> 909.8053 | E32: =(D32-$D$15-$D$16)/(1-$D$9) -> 1146.3605 | F32: =E32/$D$12 -> 7.9279024 | G32: =$D$7-F32 -> -0.67790238 | J32: Strong outcome
C34: Sensitivity: Sponsor IRR by Exit Multiple and Exit Year
C35: Exit multiple \ exit year | D35: 3 | E35: 4 | F35: 5
C36: 6 | D36: =IFERROR((($C36*INDEX('Operating Model'!$G$14:$K$14,D$35)*(1-$D$9)-INDEX('Debt Waterfall'!$G$69:$K$69,D$35)+INDEX('Debt Waterfall'!$G$65:$K$65,D$35))/$D$18)^(1/D$35)-1,"n.m.") -> 0.094088442 | E36: =IFERROR((($C36*INDEX('Operating Model'!$G$14:$K$14,E$35)*(1-$D$9)-INDEX('Debt Waterfall'!$G$69:$K$69,E$35)+INDEX('Debt Waterfall'!$G$65:$K$65,E$35))/$D$18)^(1/E$35)-1,"n.m.") -> 0.14495374 | F36: =IFERROR((($C36*INDEX('Operating Model'!$G$14:$K$14,F$35)*(1-$D$9)-INDEX('Debt Waterfall'!$G$69:$K$69,F$35)+INDEX('Debt Waterfall'!$G$65:$K$65,F$35))/$D$18)^(1/F$35)-1,"n.m.") -> 0.16333436
C37: 6.5 | D37: =IFERROR((($C37*INDEX('Operating Model'!$G$14:$K$14,D$35)*(1-$D$9)-INDEX('Debt Waterfall'!$G$69:$K$69,D$35)+INDEX('Debt Waterfall'!$G$65:$K$65,D$35))/$D$18)^(1/D$35)-1,"n.m.") -> 0.14808185 | E37: =IFERROR((($C37*INDEX('Operating Model'!$G$14:$K$14,E$35)*(1-$D$9)-INDEX('Debt Waterfall'!$G$69:$K$69,E$35)+INDEX('Debt Waterfall'!$G$65:$K$65,E$35))/$D$18)^(1/E$35)-1,"n.m.") -> 0.1803324 | F37: =IFERROR((($C37*INDEX('Operating Model'!$G$14:$K$14,F$35)*(1-$D$9)-INDEX('Debt Waterfall'!$G$69:$K$69,F$35)+INDEX('Debt Waterfall'!$G$65:$K$65,F$35))/$D$18)^(1/F$35)-1,"n.m.") -> 0.18832211
C38: 7 | D38: =IFERROR((($C38*INDEX('Operating Model'!$G$14:$K$14,D$35)*(1-$D$9)-INDEX('Debt Waterfall'!$G$69:$K$69,D$35)+INDEX('Debt Waterfall'!$G$65:$K$65,D$35))/$D$18)^(1/D$35)-1,"n.m.") -> 0.19742474 | E38: =IFERROR((($C38*INDEX('Operating Model'!$G$14:$K$14,E$35)*(1-$D$9)-INDEX('Debt Waterfall'!$G$69:$K$69,E$35)+INDEX('Debt Waterfall'!$G$65:$K$65,E$35))/$D$18)^(1/E$35)-1,"n.m.") -> 0.21278857 | F38: =IFERROR((($C38*INDEX('Operating Model'!$G$14:$K$14,F$35)*(1-$D$9)-INDEX('Debt Waterfall'!$G$69:$K$69,F$35)+INDEX('Debt Waterfall'!$G$65:$K$65,F$35))/$D$18)^(1/F$35)-1,"n.m.") -> 0.21136936
C39: 7.5 | D39: =IFERROR((($C39*INDEX('Operating Model'!$G$14:$K$14,D$35)*(1-$D$9)-INDEX('Debt Waterfall'!$G$69:$K$69,D$35)+INDEX('Debt Waterfall'!$G$65:$K$65,D$35))/$D$18)^(1/D$35)-1,"n.m.") -> 0.2430052 | E39: =IFERROR((($C39*INDEX('Operating Model'!$G$14:$K$14,E$35)*(1-$D$9)-INDEX('Debt Waterfall'!$G$69:$K$69,E$35)+INDEX('Debt Waterfall'!$G$65:$K$65,E$35))/$D$18)^(1/E$35)-1,"n.m.") -> 0.24283019 | F39: =IFERROR((($C39*INDEX('Operating Model'!$G$14:$K$14,F$35)*(1-$D$9)-INDEX('Debt Waterfall'!$G$69:$K$69,F$35)+INDEX('Debt Waterfall'!$G$65:$K$65,F$35))/$D$18)^(1/F$35)-1,"n.m.") -> 0.2327854
C40: 8 | D40: =IFERROR((($C40*INDEX('Operating Model'!$G$14:$K$14,D$35)*(1-$D$9)-INDEX('Debt Waterfall'!$G$69:$K$69,D$35)+INDEX('Debt Waterfall'!$G$65:$K$65,D$35))/$D$18)^(1/D$35)-1,"n.m.") -> 0.2854676 | E40: =IFERROR((($C40*INDEX('Operating Model'!$G$14:$K$14,E$35)*(1-$D$9)-INDEX('Debt Waterfall'!$G$69:$K$69,E$35)+INDEX('Debt Waterfall'!$G$65:$K$65,E$35))/$D$18)^(1/E$35)-1,"n.m.") -> 0.27083888 | F40: =IFERROR((($C40*INDEX('Operating Model'!$G$14:$K$14,F$35)*(1-$D$9)-INDEX('Debt Waterfall'!$G$69:$K$69,F$35)+INDEX('Debt Waterfall'!$G$65:$K$65,F$35))/$D$18)^(1/F$35)-1,"n.m.") -> 0.25280905
C41: 8.5 | D41: =IFERROR((($C41*INDEX('Operating Model'!$G$14:$K$14,D$35)*(1-$D$9)-INDEX('Debt Waterfall'!$G$69:$K$69,D$35)+INDEX('Debt Waterfall'!$G$65:$K$65,D$35))/$D$18)^(1/D$35)-1,"n.m.") -> 0.32529602 | E41: =IFERROR((($C41*INDEX('Operating Model'!$G$14:$K$14,E$35)*(1-$D$9)-INDEX('Debt Waterfall'!$G$69:$K$69,E$35)+INDEX('Debt Waterfall'!$G$65:$K$65,E$35))/$D$18)^(1/E$35)-1,"n.m.") -> 0.2971093 | F41: =IFERROR((($C41*INDEX('Operating Model'!$G$14:$K$14,F$35)*(1-$D$9)-INDEX('Debt Waterfall'!$G$69:$K$69,F$35)+INDEX('Debt Waterfall'!$G$65:$K$65,F$35))/$D$18)^(1/F$35)-1,"n.m.") -> 0.2716288
C42: 9 | D42: =IFERROR((($C42*INDEX('Operating Model'!$G$14:$K$14,D$35)*(1-$D$9)-INDEX('Debt Waterfall'!$G$69:$K$69,D$35)+INDEX('Debt Waterfall'!$G$65:$K$65,D$35))/$D$18)^(1/D$35)-1,"n.m.") -> 0.36286447 | E42: =IFERROR((($C42*INDEX('Operating Model'!$G$14:$K$14,E$35)*(1-$D$9)-INDEX('Debt Waterfall'!$G$69:$K$69,E$35)+INDEX('Debt Waterfall'!$G$65:$K$65,E$35))/$D$18)^(1/E$35)-1,"n.m.") -> 0.32187405 | F42: =IFERROR((($C42*INDEX('Operating Model'!$G$14:$K$14,F$35)*(1-$D$9)-INDEX('Debt Waterfall'!$G$69:$K$69,F$35)+INDEX('Debt Waterfall'!$G$65:$K$65,F$35))/$D$18)^(1/F$35)-1,"n.m.") -> 0.28939619
C44: Sponsor MOIC by exit multiple and exit year | D44: =D35 -> 3 | E44: =E35 -> 4 | F44: =F35 -> 5
C45: =C36 -> 6 | D45: =($C45*INDEX('Operating Model'!$G$14:$K$14,D$44)*(1-$D$9)-INDEX('Debt Waterfall'!$G$69:$K$69,D$44)+INDEX('Debt Waterfall'!$G$65:$K$65,D$44))/$D$18 -> 1.3096562 | E45: =($C45*INDEX('Operating Model'!$G$14:$K$14,E$44)*(1-$D$9)-INDEX('Debt Waterfall'!$G$69:$K$69,E$44)+INDEX('Debt Waterfall'!$G$65:$K$65,E$44))/$D$18 -> 1.7185088 | F45: =($C45*INDEX('Operating Model'!$G$14:$K$14,F$44)*(1-$D$9)-INDEX('Debt Waterfall'!$G$69:$K$69,F$44)+INDEX('Debt Waterfall'!$G$65:$K$65,F$44))/$D$18 -> 2.1307023
C46: =C37 -> 6.5 | D46: =($C46*INDEX('Operating Model'!$G$14:$K$14,D$44)*(1-$D$9)-INDEX('Debt Waterfall'!$G$69:$K$69,D$44)+INDEX('Debt Waterfall'!$G$65:$K$65,D$44))/$D$18 -> 1.5132774 | E46: =($C46*INDEX('Operating Model'!$G$14:$K$14,E$44)*(1-$D$9)-INDEX('Debt Waterfall'!$G$69:$K$69,E$44)+INDEX('Debt Waterfall'!$G$65:$K$65,E$44))/$D$18 -> 1.9409633 | F46: =($C46*INDEX('Operating Model'!$G$14:$K$14,F$44)*(1-$D$9)-INDEX('Debt Waterfall'!$G$69:$K$69,F$44)+INDEX('Debt Waterfall'!$G$65:$K$65,F$44))/$D$18 -> 2.3695774
C47: =C38 -> 7 | D47: =($C47*INDEX('Operating Model'!$G$14:$K$14,D$44)*(1-$D$9)-INDEX('Debt Waterfall'!$G$69:$K$69,D$44)+INDEX('Debt Waterfall'!$G$65:$K$65,D$44))/$D$18 -> 1.7168987 | E47: =($C47*INDEX('Operating Model'!$G$14:$K$14,E$44)*(1-$D$9)-INDEX('Debt Waterfall'!$G$69:$K$69,E$44)+INDEX('Debt Waterfall'!$G$65:$K$65,E$44))/$D$18 -> 2.1634177 | F47: =($C47*INDEX('Operating Model'!$G$14:$K$14,F$44)*(1-$D$9)-INDEX('Debt Waterfall'!$G$69:$K$69,F$44)+INDEX('Debt Waterfall'!$G$65:$K$65,F$44))/$D$18 -> 2.6084524
...
