Workbook

Sheet Revenue
A1: Eaton Corporation (NYSE: ETN)
A2: Case (1 = Base, 2 = Street, 3 = Bull) | B2: 1 | C2: =CHOOSE($B$2,"Base","Street","Bull")
A3: Power Management Company | F3: 1 | G3: 2 | H3: 3 | I3: 4 | J3: 5
B4: Historical | F4: Projected
A5: Fiscal year | B5: 2022 | C5: 2023 | D5: 2024 | E5: 2025 | F5: 2026 | G5: 2027 | H5: 2028 | I5: 2029 | J5: 2030 | Q5: Electrical:
Q6: Transformer | S6: ---> 22 % of sales made to six customer
A7: Revenue Build out | Q7: Power Supply
A8: Electrical America Product | B8: 2732 | C8: 2949 | D8: 3009 | E8: 3205 | F8: =F43*F55 | G8: =G43*G55 | H8: =H43*H55 | I8: =I43*I55 | J8: =J43*J55
A9: Electrical America Systems | B9: 5765 | C9: 7149 | D9: 8426 | E9: 10070 | F9: =F43*F48 | G9: =G43*G48 | H9: =H43*H48 | I9: =I43*I48 | J9: =J43*J48
A10: Electrical Global Product | B10: 3424 | C10: 3462 | D10: 3493 | E10: 3885 | F10: =F72*F82 | G10: =G72*G82 | H10: =H72*H82 | I10: =I72*I82 | J10: =J72*J82
A11: Electrical Global Systems | B11: 2755 | C11: 2622 | D11: 2755 | E11: 2930 | F11: =F72*F76+F295 | G11: =G72*G76+G295 | H11: =H72*H76+H295 | I11: =I72*I76+I295 | J11: =J72*J76+J295 | O11: ß
A12: Aerospace | B12: 3039 | C12: 3413 | D12: 3744 | E12: =4249 | F12: =F98+F101+F102+F296 | G12: =G98+G101+G102+G296 | H12: =H98+H101+H102+H296 | I12: =I98+I101+I102+I296 | J12: =J98+J101+J102+J296 | Q12: Main engine fuel pump | S12: --->> 20 % to three large
A13: Vehicle | B13: 2839 | C13: 2965 | D13: 2790 | E13: =2504 | F13: =(F119+F122)*F299 | G13: =(G119+G122)*G299 | H13: =(H119+H122)*H299 | I13: =(I119+I122)*I299 | J13: =(J119+J122)*J299 | Q13: Hydraulic Power Pumps
A14: Emobility | B14: 538 | C14: 636 | D14: 662 | E14: 604 | F14: =F125*F299 | G14: =G125*G299 | H14: =H125*H299 | I14: =I125*I299 | J14: =J125*J299
A15: Total Revnues | B15: =SUM(B8:B14) | C15: =SUM(C8:C14) | D15: =SUM(D8:D14) | E15: =SUM(E8:E14) | F15: =SUM(F8:F14) | G15: =SUM(G8:G14) | H15: =SUM(H8:H14) | I15: =SUM(I8:I14) | J15: =SUM(J8:J14) | Q15: Power distribution units for EV | T15: ---> made to 4 large ev
A16: growth YoY | C16: =(C15-B15)/B15 | D16: =(D15-C15)/C15 | E16: =(E15-D15)/D15 | F16: =(F15-E15)/E15 | G16: =(G15-F15)/F15 | H16: =(H15-G15)/G15 | I16: =(I15-H15)/H15 | J16: =(J15-I15)/I15
Q17: 180 Countries
A18: Electrical | B18: =SUM(B8:B11) | C18: =SUM(C8:C11) | D18: =SUM(D8:D11) | E18: =SUM(E8:E11) | F18: =SUM(F8:F11) | G18: =SUM(G8:G11) | H18: =SUM(H8:H11) | I18: =SUM(I8:I11) | J18: =SUM(J8:J11)
A19: Aersospace | B19: =B12 | C19: =C12 | D19: =D12 | E19: =E12 | F19: =F12 | G19: =G12 | H19: =H12 | I19: =I12 | J19: =J12 | Q19: Datacentre play
A20: Vehicle & Emobility | B20: =B13+B14 | C20: =C13+C14 | D20: =D13+D14 | E20: =E13+E14 | F20: =F13+F14 | G20: =G13+G14 | H20: =H13+H14 | I20: =I13+I14 | J20: =J13+J14
A22: Electrical Growth YoY | C22: =(C18-B18)/B18 | D22: =(D18-C18)/C18 | E22: =(E18-D18)/D18 | F22: =(F18-E18)/E18 | G22: =(G18-F18)/F18 | H22: =(H18-G18)/G18 | I22: =(I18-H18)/H18 | J22: =(J18-I18)/I18
A23: Aerospace | C23: =(C12-B12)/B12 | D23: =(D12-C12)/C12 | E23: =(E12-D12)/D12 | F23: =(F12-E12)/E12 | G23: =(G12-F12)/F12 | H23: =(H12-G12)/G12 | I23: =(I12-H12)/H12 | J23: =(J12-I12)/I12
A24: Vehicle & Emobility Growth | C24: =(C20-B20)/B20 | D24: =(D20-C20)/C20 | E24: =(E20-D20)/D20 | F24: =(F20-E20)/E20 | G24: =(G20-F20)/F20 | H24: =(H20-G20)/G20 | I24: =(I20-H20)/H20 | J24: =(J20-I20)/I20 | Q24: Raw materials
A25: Equipment as a % of Revenue | B25: =(B12+B14+B10+B8)/B15 | C25: =(C12+C14+C10+C8)/C15 | D25: =(D12+D14+D10+D8)/D15 | E25: =(E12+E14+E10+E8)/E15 | F25: =(F12+F14+F10+F8)/F15 | G25: =(G12+G14+G10+G8)/G15 | H25: =(H12+H14+H10+H8)/H15 | I25: =(I12+I14+I10+I8)/I15 | J25: =(J12+J14+J10+J8)/J15 | Q25: Intellectual property
A26: Data-Centre exposed equipment as a % of Revenue | B26: =(B9+B11)/B15 | C26: =(C9+C11)/C15 | D26: =(D9+D11)/D15 | E26: =(E9+E11)/E15 | F26: =(F9+F11)/F15 | G26: =(G9+G11)/G15 | H26: =(H9+H11)/H15 | I26: =(I9+I11)/I15 | J26: =(J9+J11)/J15
A27: Total Data Centre Exposed Equipment | B27: =B9+B11 | C27: =C9+C11 | D27: =D9+D11 | E27: =E9+E11 | F27: =F9+F11 | G27: =G9+G11 | H27: =H9+H11 | I27: =I9+I11 | J27: =J9+J11
A28: Growth | C28: =(C27-B27)/B27 | D28: =(D27-C27)/C27 | E28: =(E27-D27)/D27 | F28: =(F27-E27)/E27 | G28: =(G27-F27)/F27 | H28: =(H27-G27)/G27 | I28: =(I27-H27)/H27 | J28: =(J27-I27)/I27 | Q28: Reslliance acquisition
A30: 1. Data Centre Demand (B)
A31: Microsoft | B31: 23.9 | C31: 28.1 | D31: 74.5 | E31: 108.3 | F31: 175 | G31: =$F$31+($J$31-$F$31)*(G$3/4) | H31: =$F$31+($J$31-$F$31)*(H$3/4) | I31: 315 | J31: 338
A32: Amazon | B32: 63 | C32: 52.7 | D32: 83.9 | E32: 134.8 | F32: 220 | G32: 370 | H32: 400 | I32: 415 | J32: 435
A33: Alphabet | B33: 31 | C33: 32.3 | D33: 52.9 | E33: 93 | F33: 200 | G33: 245 | H33: 280 | I33: 320 | J33: 340
A34: Meta | B34: 31.2 | C34: 27 | D34: 38.4 | E34: 72.6 | F34: 137.5 | G34: 186 | H34: 330 | I34: 370 | J34: 405 | L34: =SUM(J31:J34)
A35: Hyperscaler capex, big four | B35: =SUM(B31:B34)*1000 | C35: =SUM(C31:C34)*1000 | D35: =SUM(D31:D34)*1000 | E35: =SUM(E31:E34)*1000 | F35: =SUM(F31:F34)*1000 | G35: =(F35*G36)+F35 | H35: =(G35*H36)+G35 | I35: =(H35*I36)+H35 | J35: =(I35*J36)+I35
A36: Capex Growth YoY | C36: =(C35-B35)/B35 | D36: =(D35-C35)/C35 | E36: =(E35-D35)/D35 | F36: =(F35-E35)/E35 | G36: =G177 | H36: =H177 | I36: =I177 | J36: =J177
A39: 2. Electrical Americas
A40: America
A41: Back-Log Americas | B41: X | C41: 6740 | D41: 7953 | E41: 10141 | F41: 13246 | G41: =F41+F42-F43 | H41: =G41+G42-G43 | I41: =H41+H42-H43 | J41: =I41+I42-I43
A42: New Orders | C42: =D41+C43-C41 | D42: =E41+D43-D41 | E42: =F41+E43-E41 | F42: =F56+F49 | G42: =G56+G49 | H42: =H56+H49 | I42: =I56+I49 | J42: =J56+J49
A43: Revenue | C43: =SUM(C8:C9) | D43: =SUM(D8:D9) | E43: =SUM(E8:E9) | F43: =(F41+F42)*F44 | G43: =(G41+G42)*G44 | H43: =(H41+H42)*H44 | I43: =(I41+I42)*I44 | J43: =(J41+J42)*J44
A44: Revenue Recognition % | C44: =C43/(C42+C41) | D44: =D43/(D42+D41) | E44: =E43/(E42+E41) | F44: =F184 | G44: =G184 | H44: =H184 | I44: =I184 | J44: =J184
...

Sheet Income Statement
A1: Eaton Corporation (NYSE: ETN): Income Statement
B4: Historical | F4: Projected
A5: Fiscal year ending Dec 31 ($mm) | B5: 2022A | C5: 2023A | D5: 2024A | E5: 2025A | F5: 2026E | G5: 2027E | H5: 2028E | I5: 2029E | J5: 2030E
A7: Income statement
A8: Net sales | B8: 20752 | C8: 23196 | D8: 24878 | E8: 27448 | F8: =Revenue!F15 | G8: =Revenue!G15 | H8: =Revenue!H15 | I8: =Revenue!I15 | J8: =Revenue!J15
A9: growth YoY | C9: =IF(B8=0,0,C8/B8-1) | D9: =IF(C8=0,0,D8/C8-1) | E9: =IF(D8=0,0,E8/D8-1) | F9: =(F8-E8)/E8 | G9: =(G8-F8)/F8 | H9: =(H8-G8)/G8 | I9: =(I8-H8)/H8 | J9: =(J8-I8)/I8
A10: Cost of products sold | B10: 13865 | C10: 14762 | D10: 15375 | E10: 17131 | F10: =F8*F11 | G10: =G8*G11 | H10: =H8*H11 | I10: =I8*I11 | J10: =J8*J11
A11: % of Net Sales | B11: =B10/B8 | C11: =C10/C8 | D11: =D10/D8 | E11: =E10/E8 | F11: =AVERAGE(B11:E11) | G11: =AVERAGE(C11:F11) | H11: =AVERAGE(D11:G11) | I11: =AVERAGE(E11:H11) | J11: =AVERAGE(F11:I11)
A12: Gross profit | B12: =B8-B10 | C12: =C8-C10 | D12: =D8-D10 | E12: =E8-E10 | F12: =F8-F10 | G12: =G8-G10 | H12: =H8-H10 | I12: =I8-I10 | J12: =J8-J10
A13: Selling and administrative expense | B13: 3227 | C13: 3795 | D13: 4077 | E13: 4311 | F13: =F12*F14 | G13: =G12*G14 | H13: =H12*H14 | I13: =I12*I14 | J13: =J12*J14
A14: % of Gross Profit | B14: =B13/B12 | C14: =C13/C12 | D14: =D13/D12 | E14: =E13/E12 | F14: =AVERAGE(B14:E14) | G14: 0.44135121 | H14: 0.44135121 | I14: 0.44135121 | J14: 0.44135121
A15: Research and development expense | B15: 665 | C15: 754 | D15: 794 | E15: 797 | F15: =AVERAGE(B15:E15) | G15: =AVERAGE(C15:F15) | H15: =AVERAGE(D15:G15) | I15: =AVERAGE(E15:H15) | J15: =AVERAGE(F15:I15)
A16: Operating income (EBIT, before other items) | B16: =B12-B13-B15 | C16: =C12-C13-C15 | D16: =D12-D13-D15 | E16: =E12-E13-E15 | F16: =F12-F13-F15 | G16: =G12-G13-G15 | H16: =H12-H13-H15 | I16: =I12-I13-I15 | J16: =J12-J13-J15
A17: Interest expense - net | B17: 144 | C17: 151 | D17: 130 | E17: 241 | F17: =AVERAGE(B17:E17) | G17: =AVERAGE(C17:F17) | H17: =AVERAGE(D17:G17) | I17: =AVERAGE(E17:H17) | J17: =AVERAGE(F17:I17)
A18: Gain on sale of business | B18: 24 | C18: 0 | D18: 0 | E18: 0
A19: Other expense (income) - net | B19: -36 | C19: -93 | D19: -64 | E19: 37 | F19: =AVERAGE(B19:E19) | G19: =AVERAGE(C19:F19) | H19: =AVERAGE(D19:G19) | I19: =AVERAGE(E19:H19) | J19: =AVERAGE(F19:I19)
A20: Income before income taxes | B20: 2911 | C20: 3827 | D20: 4566 | E20: 4932 | F20: =F16+F17-F19 | G20: =G16+G17-G19 | H20: =H16+H17-H19 | I20: =I16+I17-I19 | J20: =J16+J17-J19
A21: Income tax expense | B21: 445 | C21: 604 | D21: 768 | E21: 841 | F21: =F20*F22 | G21: =G20*G22 | H21: =H20*H22 | I21: =I20*I22 | J21: =J20*J22
A22: Tax % | B22: =B21/B20 | C22: =C21/C20 | D22: =D21/D20 | E22: =E21/E20 | F22: =E22 | G22: =F22 | H22: =G22 | I22: =H22 | J22: =I22
A23: Net income | B23: 2465 | C23: 3223 | D23: 3798 | E23: 4090 | F23: =F20-F21 | G23: =G20-G21 | H23: =H20-H21 | I23: =I20-I21 | J23: =J20-J21
A24: Less net income for noncontrolling interests | B24: 4 | C24: 5 | D24: 4 | E24: 3 | F24: =3 | G24: =3 | H24: =3 | I24: =3 | J24: =3
A25: Net income attributable to Eaton shareholders | B25: 2462 | C25: 3218 | D25: 3794 | E25: 4087 | F25: =F23+F24 | G25: =G23+G24 | H25: =H23+H24 | I25: =I23+I24 | J25: =J23+J24
A27: Per share
A28: Weighted avg shares - basic (mm) | B28: 398.7 | C28: 399.1 | D28: 397.6 | E28: 389.9 | F28: =E28 | G28: =F28 | H28: =G28 | I28: =H28 | J28: =I28
A29: Weighted avg shares - diluted (mm) | B29: 400.8 | C29: 401.1 | D29: 399.4 | E29: 391.2 | F29: =E29 | G29: =F29 | H29: =G29 | I29: =H29 | J29: =I29
A30: EPS - basic | B30: =IF(B28=0,0,B25/B28) | C30: =IF(C28=0,0,C25/C28) | D30: =IF(D28=0,0,D25/D28) | E30: =IF(E28=0,0,E25/E28) | F30: =F25/F29 | G30: =G25/G29 | H30: =H25/H29 | I30: =I25/I29 | J30: =J25/J29
A31: EPS - diluted | B31: =IF(B29=0,0,B25/B29) | C31: =IF(C29=0,0,C25/C29) | D31: =IF(D29=0,0,D25/D29) | E31: =IF(E29=0,0,E25/E29) | F31: =F25/F29 | G31: =G25/G29 | H31: =H25/H29 | I31: =I25/I29 | J31: =J25/J29
A32: Dividends declared per share | B32: 3.24 | C32: 3.44 | D32: 3.76 | E32: 4.16 | F32: =E32*(1+E33) | G32: =F32*(1+F33) | H32: =G32*(1+G33) | I32: =H32*(1+H33) | J32: =I32*(1+I33)
A33: %Growth | C33: =(C32-C32)/B32 | D33: =(D32-D32)/C32 | E33: =(E32-D32)/D32 | F33: 0.1064 | G33: 0.1064 | H33: 0.1064 | I33: 0.1063 | J33: 0.1064
A34: Margins
A35: Gross margin | B35: =IF(B8=0,0,B12/B8) | C35: =IF(C8=0,0,C12/C8) | D35: =IF(D8=0,0,D12/D8) | E35: =IF(E8=0,0,E12/E8) | F35: =(F25)/F12 | G35: =(G25)/G12 | H35: =(H25)/H12 | I35: =(I25)/I12 | J35: =(J25)/J12
A36: EBIT margin | B36: =IF(B8=0,0,B16/B8) | C36: =IF(C8=0,0,C16/C8) | D36: =IF(D8=0,0,D16/D8) | E36: =IF(E8=0,0,E16/E8) | F36: =F16/F8 | G36: =G16/G8 | H36: =H16/H8 | I36: =I16/I8 | J36: =J16/J8
A37: Depreciation and amortization (from cash flow) | B37: ='Cash Flow'!B10 | C37: ='Cash Flow'!C10 | D37: ='Cash Flow'!D10 | E37: ='Cash Flow'!E10 | F37: 1090 | G37: 1200 | H37: 1290 | I37: 1350 | J37: 1280
A38: EBITDA | B38: =B16+B37 | C38: =C16+C37 | D38: =D16+D37 | E38: =E16+E37 | F38: =F16+F37 | G38: =G16+G37 | H38: =H16+H37 | I38: =I16+I37 | J38: =J16+J37
A39: EBITDA margin | B39: =IF(B8=0,0,B38/B8) | C39: =IF(C8=0,0,C38/C8) | D39: =IF(D8=0,0,D38/D8) | E39: =IF(E8=0,0,E38/E8) | F39: =F38/F8 | G39: =G38/G8 | H39: =H38/H8 | I39: =I38/I8 | J39: =J38/J8
A40: Effective tax rate | B40: =IF(B20=0,0,B21/B20) | C40: =IF(C20=0,0,C21/C20) | D40: =IF(D20=0,0,D21/D20) | E40: =IF(E20=0,0,E21/E20) | F40: =F22 | G40: =G22 | H40: =H22 | I40: =I22 | J40: =J22

Sheet DCF
A1: Eaton Corporation (NYSE: ETN)
A2: Case (1 = Base, 2 = Street, 3 = Bull) | B2: 1 | C2: =CHOOSE($B$2,"Base","Street","Bull")
A3: Power Management Company | F3: 1 | G3: 2 | H3: 3 | I3: 4 | J3: 5
B4: Historical | F4: Projected
A5: Fiscal year | B5: 2022 | C5: 2023 | D5: 2024 | E5: 2025 | F5: 2026 | G5: 2027 | H5: 2028 | I5: 2029 | J5: 2030
A6: Revenue | B6: =Revenue!B15 | C6: =Revenue!C15 | D6: =Revenue!D15 | E6: =Revenue!E15 | F6: =Revenue!F15 | G6: =Revenue!G15 | H6: =Revenue!H15 | I6: =Revenue!I15 | J6: =Revenue!J15
A7: Growth, YoY | C7: =C6/B6-1 | D7: =D6/C6-1 | E7: =E6/D6-1 | F7: =F6/E6-1 | G7: =G6/F6-1 | H7: =H6/G6-1 | I7: =I6/H6-1 | J7: =J6/I6-1
A8: Adjusted EBITDA | B8: ='Income Statement'!B38 | C8: ='Income Statement'!C38 | D8: ='Income Statement'!D38 | E8: ='Income Statement'!E38 | F8: =F6*F9 | G8: =G6*G9 | H8: =H6*H9 | I8: =I6*I9 | J8: =J6*J9 | K8: Was ='Income Statement'!F38 (IS cost ratios gave 21.3-22.2% margins)
A9: EBITDA margin (Street path, tracks 2026 guide) | B9: =B8/B6 | C9: =C8/C6 | D9: =D8/D6 | E9: =E8/E6 | F9: ='Consensus DCF'!F9 | G9: ='Consensus DCF'!G9 | H9: ='Consensus DCF'!H9 | I9: ='Consensus DCF'!I9 | J9: ='Consensus DCF'!J9
A10: D&A | B10: ='Income Statement'!B37 | C10: ='Income Statement'!C37 | D10: ='Income Statement'!D37 | E10: ='Income Statement'!E37 | F10: ='Income Statement'!F37 | G10: ='Income Statement'!G37 | H10: ='Income Statement'!H37 | I10: ='Income Statement'!I37 | J10: ='Income Statement'!J37
A11: Adjusted EBIT | B11: =B8-B10 | C11: =C8-C10 | D11: =D8-D10 | E11: =E8-E10 | F11: =F8-F10 | G11: =G8-G10 | H11: =H8-H10 | I11: =I8-I10 | J11: =J8-J10
A12: Taxes | B12: =B11*'Income Statement'!B22 | C12: =C11*'Income Statement'!C22 | D12: =D11*'Income Statement'!D22 | E12: =E11*'Income Statement'!E22 | F12: ='Income Statement'!F40*DCF!F11 | G12: ='Income Statement'!G40*DCF!G11 | H12: ='Income Statement'!H40*DCF!H11 | I12: ='Income Statement'!I40*DCF!I11 | J12: ='Income Statement'!J40*DCF!J11
A13: NOPAT | B13: =B11-B12 | C13: =C11-C12 | D13: =D11-D12 | E13: =E11-E12 | F13: =F11-F12 | G13: =G11-G12 | H13: =H11-H12 | I13: =I11-I12 | J13: =J11-J12
A14: Add back: D&A | B14: =B10 | C14: =C10 | D14: =D10 | E14: =E10 | F14: =F10 | G14: =G10 | H14: =H10 | I14: =I10 | J14: =J10
A15: Capex | B15: ='Cash Flow'!B29 | C15: ='Cash Flow'!C29 | D15: ='Cash Flow'!D29 | E15: ='Cash Flow'!E29 | F15: ='Cash Flow'!F29 | G15: ='Cash Flow'!G29 | H15: ='Cash Flow'!H29 | I15: ='Cash Flow'!I29 | J15: ='Cash Flow'!J29
A16: Less: increase in working capital | C16: =-(C21-B21) | D16: =-(D21-C21) | E16: =-(E21-D21) | F16: =-(F21-E21) | G16: =-(G21-F21) | H16: =-(H21-G21) | I16: =-(I21-H21) | J16: =-(J21-I21)
A17: Unlevered free cash flow | C17: =C13+C14+C15+C16 | D17: =D13+D14+D15+D16 | E17: =E13+E14+E15+E16 | F17: =F13+F14+F15+F16 | G17: =G13+G14+G15+G16 | H17: =H13+H14+H15+H16 | I17: =I13+I14+I15+I16 | J17: =J13+J14+J15+J16
A18: Share of year after 30-Jun-26 valuation date | F18: 0.5 | G18: 1 | H18: 1 | I18: 1 | J18: 1
A19: PV of Cash flows | F19: =F17*F18/(1+WACC!$D$49)^F20 | G19: =G17*G18/(1+WACC!$D$49)^G20 | H19: =H17*H18/(1+WACC!$D$49)^H20 | I19: =I17*I18/(1+WACC!$D$49)^I20 | J19: =J17*J18/(1+WACC!$D$49)^J20
A20: Discount period (years from 30-Jun-26) | F20: 0.5 | G20: 1.5 | H20: 2.5 | I20: 3.5 | J20: 4.5
A21: Working capital balance (current assets - current liabilities) | B21: ='Balance Sheet'!B13-'Balance Sheet'!B30 | C21: ='Balance Sheet'!C13-'Balance Sheet'!C30 | D21: ='Balance Sheet'!D13-'Balance Sheet'!D30 | E21: ='Balance Sheet'!E13-'Balance Sheet'!E30 | F21: =AVERAGE(B21:E21) | G21: =AVERAGE(C21:F21) | H21: =AVERAGE(D21:G21) | I21: =AVERAGE(E21:H21) | J21: =AVERAGE(F21:I21)
A23: Valuation
A24: Exit multiple (EV / FY2030E EBITDA) | B24: 22
A25: FY2030E EBITDA | B25: =J8
A26: Exit value, Dec-30 | B26: =B25*B24
A27: Years from valuation date (30-Jun-26 to Dec-30) | B27: 4.5
A28: Discount rate (WACC) | B28: =WACC!D49
A29: PV of exit value | B29: =B26/((1+B28)^B27)
A31: Enterprise value, 30-Jun-26 | B31: =B29+SUM(F19:J19)
A32: Exit value % of EV | B32: =B29/B31
A33: Cash and short-term investments, 30-Jun-26 | B33: 695
A34: Total debt, 30-Jun-26 (incl. Boyd financing) | B34: 20611
A35: Noncontrolling interests | B35: 44
A36: Pension and OPEB | B36: 671
A37: Equity-method investments | B37: 903
A38: Equity value, 30-Jun-26 | B38: =B31+B33-B34-B35-B36+B37
A39: Diluted shares (mm) | B39: 388
A41: Value per share, 30-Jun-26 | B41: =B38/B39
A42: Cost of equity | B42: =WACC!D30
A43: Carry to 6-month target date, 15-Apr-27 (years) | B43: 0.79
...

Sheet Consensus DCF
A1: Eaton Corporation (NYSE: ETN) - Consensus DCF
A3: Discount period | F3: =DCF!F3 | G3: =DCF!G3 | H3: =DCF!H3 | I3: =DCF!I3 | J3: =DCF!J3
B4: Historical | F4: Consensus
A5: Fiscal year ($mm) | B5: 2022 | C5: 2023 | D5: 2024 | E5: 2025 | F5: 2026 | G5: 2027 | H5: 2028 | I5: 2029 | J5: 2030
A6: Revenue | B6: =DCF!B6 | C6: =DCF!C6 | D6: =DCF!D6 | E6: =DCF!E6 | F6: 32863 | G6: 36788 | H6: 40333 | I6: =H6*(1+I7) | J6: =I6*(1+J7)
A7: Growth, YoY | C7: =C6/B6-1 | D7: =D6/C6-1 | E7: =E6/D6-1 | F7: =F6/E6-1 | G7: =G6/F6-1 | H7: =H6/G6-1 | I7: =H7 | J7: =I7
A8: EBITDA | B8: =DCF!B8 | C8: =DCF!C8 | D8: =DCF!D8 | E8: =DCF!E8 | F8: 7802 | G8: 9098 | H8: 10216 | I8: =I6*I9 | J8: =J6*J9
A9: Margin | B9: =B8/B6 | C9: =C8/C6 | D9: =D8/D6 | E9: =E8/E6 | F9: =F8/F6 | G9: =G8/G6 | H9: =H8/H6 | I9: =H9 | J9: =I9
A10: D&A | B10: =DCF!B10 | C10: =DCF!C10 | D10: =DCF!D10 | E10: =DCF!E10 | F10: 1276 | G10: 1248 | H10: 1251 | I10: =I6*I11 | J10: =J6*J11
A11: D&A % of revenue | B11: =B10/B6 | C11: =C10/C6 | D11: =D10/D6 | E11: =E10/E6 | F11: =F10/F6 | G11: =G10/G6 | H11: =H10/H6 | I11: =H11 | J11: =I11
A12: EBIT | B12: =B8-B10 | C12: =C8-C10 | D12: =D8-D10 | E12: =E8-E10 | F12: =F8-F10 | G12: =G8-G10 | H12: =H8-H10 | I12: =I8-I10 | J12: =J8-J10
A13: Taxes | B13: =B12*'Income Statement'!B40 | C13: =C12*'Income Statement'!C40 | D13: =D12*'Income Statement'!D40 | E13: =E12*'Income Statement'!E40 | F13: =F12*'Income Statement'!F40 | G13: =G12*'Income Statement'!G40 | H13: =H12*'Income Statement'!H40 | I13: =I12*'Income Statement'!I40 | J13: =J12*'Income Statement'!J40
A14: NOPAT | B14: =B12-B13 | C14: =C12-C13 | D14: =D12-D13 | E14: =E12-E13 | F14: =F12-F13 | G14: =G12-G13 | H14: =H12-H13 | I14: =I12-I13 | J14: =J12-J13
A15: Add back: D&A | B15: =B10 | C15: =C10 | D15: =D10 | E15: =E10 | F15: =F10 | G15: =G10 | H15: =H10 | I15: =I10 | J15: =J10
A16: Capex | B16: =DCF!B15 | C16: =DCF!C15 | D16: =DCF!D15 | E16: =DCF!E15 | F16: -1124 | G16: -1171 | H16: -1269 | I16: =-I6*I17 | J16: =-J6*J17
A17: Capex % of revenue | B17: =-B16/B6 | C17: =-C16/C6 | D17: =-D16/D6 | E17: =-E16/E6 | F17: =-F16/F6 | G17: =-G16/G6 | H17: =-H16/H6 | I17: =H17 | J17: =I17
A18: Change in working capital | C18: =-('Balance Sheet'!C56-'Balance Sheet'!B56) | D18: =-('Balance Sheet'!D56-'Balance Sheet'!C56) | E18: =-('Balance Sheet'!E56-'Balance Sheet'!D56) | F18: =-'Balance Sheet'!$E$57*(F6-E6) | G18: =-'Balance Sheet'!$E$57*(G6-F6) | H18: =-'Balance Sheet'!$E$57*(H6-G6) | I18: =-'Balance Sheet'!$E$57*(I6-H6) | J18: =-'Balance Sheet'!$E$57*(J6-I6)
A19: Unlevered free cash flow | C19: =C14+C15+C16+C18 | D19: =D14+D15+D16+D18 | E19: =E14+E15+E16+E18 | F19: =F14+F15+F16+F18 | G19: =G14+G15+G16+G18 | H19: =H14+H15+H16+H18 | I19: =I14+I15+I16+I18 | J19: =J14+J15+J16+J18
A20: Share of year after 30-Jun-26 valuation date | F20: 0.5 | G20: 1 | H20: 1 | I20: 1 | J20: 1
A21: PV of cash flows | F21: =F19*F20/(1+WACC!$D$49)^F22 | G21: =G19*G20/(1+WACC!$D$49)^G22 | H21: =H19*H20/(1+WACC!$D$49)^H22 | I21: =I19*I20/(1+WACC!$D$49)^I22 | J21: =J19*J20/(1+WACC!$D$49)^J22
A22: Discount period (years from 30-Jun-26) | F22: 0.5 | G22: 1.5 | H22: 2.5 | I22: 3.5 | J22: 4.5
A24: Valuation
A25: Exit multiple (EV / FY2030E EBITDA) | B25: =DCF!B24
A26: FY2030E EBITDA | B26: =J8
A27: Exit value, Dec-30 | B27: =B26*B25
A28: Years from valuation date (30-Jun-26 to Dec-30) | B28: =DCF!B27
A29: Discount rate | B29: =WACC!D49
A30: PV of exit value | B30: =B27/((1+B29)^B28)
A32: Enterprise value, 30-Jun-26 | B32: =B30+SUM(F21:J21)
A33: Exit value % of EV | B33: =B30/B32
A34: Cash and short-term investments, 30-Jun-26 | B34: =DCF!B33
A35: Total debt, 30-Jun-26 | B35: =DCF!B34
A36: Noncontrolling interests | B36: =DCF!B35
A37: Pension and OPEB | B37: =DCF!B36
A38: Equity-method investments | B38: =DCF!B37
A39: Equity value, 30-Jun-26 | B39: =B32+B34-B35-B36-B37+B38
A40: Diluted shares (mm) | B40: =DCF!B39
A42: Value per share, 30-Jun-26 | B42: =B39/B40
A43: Current share price | B43: ='Reverse DCF'!B25
A44: Upside / (downside) | B44: =B42/B43-1
...

Sheet Reverse DCF
A1: Eaton Corporation (NYSE: ETN) - Reverse DCF
A3: Discount period | F3: =DCF!F3 | G3: =DCF!G3 | H3: =DCF!H3 | I3: =DCF!I3 | J3: =DCF!J3
B4: Historical | F4: Implied by current price
A5: Fiscal year ($mm) | B5: 2022 | C5: 2023 | D5: 2024 | E5: 2025 | F5: 2026 | G5: 2027 | H5: 2028 | I5: 2029 | J5: 2030
A6: Revenue | B6: =DCF!B6 | C6: =DCF!C6 | D6: =DCF!D6 | E6: =DCF!E6 | F6: =E6*(1+F7) | G6: =F6*(1+G7) | H6: =G6*(1+H7) | I6: =H6*(1+I7) | J6: =I6*(1+J7)
A7: Growth, YoY | C7: =C6/B6-1 | D7: =D6/C6-1 | E7: =E6/D6-1 | F7: =$B$26 | G7: =$B$26 | H7: =$B$26 | I7: =$B$26 | J7: =$B$26
A8: EBITDA | B8: =DCF!B8 | C8: =DCF!C8 | D8: =DCF!D8 | E8: =DCF!E8 | F8: =F6*F9 | G8: =G6*G9 | H8: =H6*H9 | I8: =I6*I9 | J8: =J6*J9
A9: Margin | B9: =B8/B6 | C9: =C8/C6 | D9: =D8/D6 | E9: =E8/E6 | F9: ='Consensus DCF'!F9 | G9: ='Consensus DCF'!G9 | H9: ='Consensus DCF'!H9 | I9: ='Consensus DCF'!I9 | J9: ='Consensus DCF'!J9
A10: D&A | B10: =DCF!B10 | C10: =DCF!C10 | D10: =DCF!D10 | E10: =DCF!E10 | F10: =F6*F11 | G10: =G6*G11 | H10: =H6*H11 | I10: =I6*I11 | J10: =J6*J11
A11: D&A % of revenue | B11: =B10/B6 | C11: =C10/C6 | D11: =D10/D6 | E11: =E10/E6 | F11: ='Consensus DCF'!F11 | G11: ='Consensus DCF'!G11 | H11: ='Consensus DCF'!H11 | I11: ='Consensus DCF'!I11 | J11: ='Consensus DCF'!J11
A12: EBIT | B12: =B8-B10 | C12: =C8-C10 | D12: =D8-D10 | E12: =E8-E10 | F12: =F8-F10 | G12: =G8-G10 | H12: =H8-H10 | I12: =I8-I10 | J12: =J8-J10
A13: Taxes | B13: =B12*'Income Statement'!B40 | C13: =C12*'Income Statement'!C40 | D13: =D12*'Income Statement'!D40 | E13: =E12*'Income Statement'!E40 | F13: =F12*'Income Statement'!F40 | G13: =G12*'Income Statement'!G40 | H13: =H12*'Income Statement'!H40 | I13: =I12*'Income Statement'!I40 | J13: =J12*'Income Statement'!J40
A14: NOPAT | B14: =B12-B13 | C14: =C12-C13 | D14: =D12-D13 | E14: =E12-E13 | F14: =F12-F13 | G14: =G12-G13 | H14: =H12-H13 | I14: =I12-I13 | J14: =J12-J13
A15: Add back: D&A | B15: =B10 | C15: =C10 | D15: =D10 | E15: =E10 | F15: =F10 | G15: =G10 | H15: =H10 | I15: =I10 | J15: =J10
A16: Capex | B16: =DCF!B15 | C16: =DCF!C15 | D16: =DCF!D15 | E16: =DCF!E15 | F16: =-F6*F17 | G16: =-G6*G17 | H16: =-H6*H17 | I16: =-I6*I17 | J16: =-J6*J17
A17: Capex % of revenue | B17: =-B16/B6 | C17: =-C16/C6 | D17: =-D16/D6 | E17: =-E16/E6 | F17: ='Consensus DCF'!F17 | G17: ='Consensus DCF'!G17 | H17: ='Consensus DCF'!H17 | I17: ='Consensus DCF'!I17 | J17: ='Consensus DCF'!J17
A18: Change in working capital | C18: =-('Balance Sheet'!C56-'Balance Sheet'!B56) | D18: =-('Balance Sheet'!D56-'Balance Sheet'!C56) | E18: =-('Balance Sheet'!E56-'Balance Sheet'!D56) | F18: =-'Balance Sheet'!$E$57*(F6-E6) | G18: =-'Balance Sheet'!$E$57*(G6-F6) | H18: =-'Balance Sheet'!$E$57*(H6-G6) | I18: =-'Balance Sheet'!$E$57*(I6-H6) | J18: =-'Balance Sheet'!$E$57*(J6-I6)
A19: Unlevered free cash flow | C19: =C14+C15+C16+C18 | D19: =D14+D15+D16+D18 | E19: =E14+E15+E16+E18 | F19: =F14+F15+F16+F18 | G19: =G14+G15+G16+G18 | H19: =H14+H15+H16+H18 | I19: =I14+I15+I16+I18 | J19: =J14+J15+J16+J18
A20: Share of year after 30-Jun-26 valuation date | F20: 0.5 | G20: 1 | H20: 1 | I20: 1 | J20: 1
A21: PV of cash flows | F21: =F19*F20/(1+WACC!$D$49)^F22 | G21: =G19*G20/(1+WACC!$D$49)^G22 | H21: =H19*H20/(1+WACC!$D$49)^H22 | I21: =I19*I20/(1+WACC!$D$49)^I22 | J21: =J19*J20/(1+WACC!$D$49)^J22
A22: Discount period (years from 30-Jun-26) | F22: 0.5 | G22: 1.5 | H22: 2.5 | I22: 3.5 | J22: 4.5
A24: Valuation
A25: Current share price | B25: 408.85
A26: Implied revenue growth, FY2026-30 | B26: 0.093696415 | C26: Solved so B44 = current price (corrected model)
A27: Exit multiple (EV / FY2030E EBITDA) | B27: =DCF!B24
A28: FY2030E EBITDA | B28: =J8
A29: Exit value, Dec-30 | B29: =B28*B27
A30: Years from valuation date (30-Jun-26 to Dec-30) | B30: =DCF!B27
A31: Discount rate | B31: =WACC!D49
A32: PV of exit value | B32: =B29/((1+B31)^B30)
A34: Enterprise value, 30-Jun-26 | B34: =B32+SUM(F21:J21)
A35: Exit value % of EV | B35: =B32/B34
A36: Cash and short-term investments, 30-Jun-26 | B36: =DCF!B33
A37: Total debt, 30-Jun-26 | B37: =DCF!B34
A38: Noncontrolling interests | B38: =DCF!B35
A39: Pension and OPEB | B39: =DCF!B36
A40: Equity-method investments | B40: =DCF!B37
A41: Equity value, 30-Jun-26 | B41: =B34+B36-B37-B38-B39+B40
A42: Diluted shares (mm) | B42: =DCF!B39
A44: Share price | B44: =B41/B42
...

Sheet WACC
B5: Beta
B6: Unlevered beta = levered beta / (1 + D/E x (1 - tax))
B7: Company | C7: Ticker | D7: Currency | E7: Levered beta | F7: Tax rate | G7: Debt (bn) | H7: Market cap (bn) | I7: Debt / equity | J7: Unlevered beta
B8: Siemens Energy AG | C8: ETR:ENR | D8: EUR | E8: 1.87 | F8: 0.3 | G8: 2.96 | H8: 120.5 | I8: =G8/H8 | J8: =E8/(1+I8*(1-F8))
B9: Mitsubishi Heavy Industries | C9: TYO:7011 | D9: JPY | E9: 0.37 | F9: 0.3 | G9: 853.82 | H9: 12640 | I9: =G9/H9 | J9: =E9/(1+I9*(1-F9))
B10: GE Aerospace | C10: NYSE:GE | D10: USD | E10: 1.35 | F10: 0.25 | G10: 20.23 | H10: 324.12 | I10: =G10/H10 | J10: =E10/(1+I10*(1-F10))
B11: Eaton Corporation plc | C11: NYSE:ETN | D11: USD | E11: 1.13 | F11: 0.25 | G11: 21.33 | H11: 169.84 | I11: =G11/H11 | J11: =E11/(1+I11*(1-F11))
B12: Schneider Electric SE | C12: EPA:SU | D12: EUR | E12: 1.15 | F12: 0.25 | G12: 20.81 | H12: 164.2 | I12: =G12/H12 | J12: =E12/(1+I12*(1-F12))
B13: ABB Ltd | C13: SWX:ABBN | D13: CHF | E13: 1.01 | F13: 0.2 | G13: 7.39 | H13: 146.61 | I13: =G13/H13 | J13: =E13/(1+I13*(1-F13))
B14: Hitachi, Ltd. | C14: TYO:6501 | D14: JPY | E14: 0.54 | F14: 0.3 | G14: 1060 | H14: 24710 | I14: =G14/H14 | J14: =E14/(1+I14*(1-F14))
B15: Hubbell Incorporated | C15: NYSE:HUBB | D15: USD | E15: 0.89 | F15: 0.25 | G15: 5.56 | H15: 24.67 | I15: =G15/H15 | J15: =E15/(1+I15*(1-F15))
B16: Vertiv Holdings Co | C16: NYSE:VRT | D16: USD | E16: 2.07 | F16: 0.25 | G16: 3.34 | H16: 94.75 | I16: =G16/H16 | J16: =E16/(1+I16*(1-F16))
B17: Emerson Electric Co. | C17: NYSE:EMR | D17: USD | E17: 1.23 | F17: 0.25 | G17: 13.8 | H17: 88.45 | I17: =G17/H17 | J17: =E17/(1+I17*(1-F17))
B18: Quanta Services | C18: NYSE:PWR | D18: USD | E18: 1.27 | F18: 0.25 | G18: 6.6 | H18: 99.62 | I18: =G18/H18 | J18: =E18/(1+I18*(1-F18))
B20: Peer median | E20: =MEDIAN(E8:E18) | F20: =MEDIAN(F8:F18) | I20: =MEDIAN(I8:I18) | J20: =MEDIAN(J8:J18)
B21: Peer mean | E21: =AVERAGE(E8:E18) | F21: =AVERAGE(F8:F18) | I21: =AVERAGE(I8:I18) | J21: =AVERAGE(J8:J18)
B23: Eaton (relevered) | C23: NYSE:ETN | D23: USD | E23: =1.03*(1+(0.089*(1-0.25))) | F23: 0.25 | G23: =D45/1000 | H23: =D43/1000 | I23: =G23/H23 | J23: =J20*(1+I23*(1-F23))
B26: Cost of equity
B27: Risk-free rate (US 10-year) | D27: 0.0525
B28: Equity risk premium | D28: 0.0445
B29: Beta (relevered) | D29: =J23
B30: Cost of equity | D30: =D27+D29*D28
B33: Cost of debt
B34: Notes issued Feb-26 | C34: Principal ($mm) | D34: Coupon
B35: 4.250% due 2031
B36: 4.875% due 2036
B37: 5.500% due 2056
B38: Pre-tax cost of debt | D38: 0.0351
B39: Tax rate | D39: 0.25
B40: After-tax cost of debt | D40: =D38*(1-D39)
B42: Capital structure
B43: Market capitalisation ($mm) | D43: 158800
B44: % equity | D44: =D43/D47
B45: Total debt incl. leases ($mm) | D45: 8078
B46: % debt | D46: =D45/D47
B47: Total capital ($mm) | D47: =D43+D45
B49: WACC | D49: =D44*D30+D46*D40
B52: `
B54: Note: debt in D45 is the Dec-25 balance ($8,078M). The 30-Jun-26 balance is $20,611M after the Boyd financing; using it would lower WACC to about 9.49%. The DCF keeps 9.74%.
B55: Note: the notes listed in B35:B37 look carried over from the GE Vernova model. Pre-tax cost of debt (D38) is an input.

Sheet Balance Sheet
A1: Eaton Corporation (NYSE: ETN): Balance Sheet
B4: Historical | F4: Projected
A5: Fiscal year ending Dec 31 ($mm) | B5: 2022A | C5: 2023A | D5: 2024A | E5: 2025A | F5: 2026E | G5: 2027E | H5: 2028E | I5: 2029E | J5: 2030E
A7: Assets
A8: Cash | B8: 294 | C8: 488 | D8: 555 | E8: 622
A9: Short-term investments | B9: 261 | C9: 2121 | D9: 1525 | E9: 181
A10: Accounts receivable - net | B10: 4076 | C10: 4475 | D10: 4619 | E10: 5387
A11: Inventory | B11: 3430 | C11: 3739 | D11: 4227 | E11: 4721
A12: Prepaid expenses and other current assets | B12: 685 | C12: 851 | D12: 874 | E12: 1444
A13: Total current assets | B13: 8746 | C13: 11675 | D13: 11801 | E13: 12355
A14: Gross property, plant and equipment | B14: 8013 | C14: 8738 | D14: 9062 | E14: 10028
A15: Accumulated depreciation | B15: -4867 | C15: -5208 | D15: -5333 | E15: -5712
A16: Net property, plant and equipment | B16: 3146 | C16: 3530 | D16: 3729 | E16: 4316
A17: Goodwill | B17: 14796 | C17: 14977 | D17: 14713 | E17: 15769
A18: Other intangible assets | B18: 5485 | C18: 5091 | D18: 4658 | E18: 5054
A19: Operating lease assets | B19: 570 | C19: 648 | D19: 806 | E19: 768
... A22: Total assets | B22: 35014 | C22: 38432 | D22: 38381 | E22: 41251
A24: Liabilities
A25: Short-term debt | B25: 324 | C25: 8 | D25: 0 | E25: 1
A26: Current portion of long-term debt | B26: 10 | C26: 1017 | D26: 674 | E26: 1136
A27: Accounts payable | B27: 3072 | C27: 3365 | D27: 3678 | E27: 4168
A28: Accrued compensation | B28: 467 | C28: 676 | D28: 670 | E28: 644
A29: Other current liabilities | B29: 2488 | C29: 2680 | D29: 2835 | E29: 3421
A30: Total current liabilities | B30: 6360 | C30: 7747 | D30: 7857 | E30: 9370
A31: Long-term debt | B31: 8321 | C31: 8244 | D31: 8478 | E31: 8758
A32: Pension liabilities | B32: 649 | C32: 768 | D32: 741 | E32: 702
A33: Other postretirement benefits liabilities | B33: 177 | C33: 180 | D33: 164 | E33: 161
A34: Operating lease liabilities | B34: 459 | C34: 533 | D34: 669 | E34: 637
A35: Deferred income taxes | B35: 530 | C35: 402 | D35: 275 | E35: 265
A36: Other noncurrent liabilities | B36: 1444 | C36: 1489 | D36: 1667 | E36: 1889
A37: Total noncurrent liabilities | B37: 11580 | C37: 11616 | D37: 11994 | E37: 12412
A38: Total liabilities | B38: =B49-B48 | C38: =C49-C48 | D38: =D49-D48 | E38: =E49-E48
A40: Shareholders' equity
A41: Ordinary shares | B41: 4 | C41: 4 | D41: 4 | E41: 4
A42: Capital in excess of par value | B42: 12512 | C42: 12634 | D42: 12731 | E42: 12837
A43: Retained earnings | B43: 8468 | C43: 10305 | D43: 10096 | E43: 10702
A44: Accumulated other comprehensive loss | B44: -3946 | C44: -3906 | D44: -4342 | E44: -4118
A45: Shares held in trust | B45: -1 | C45: -1 | D45: -1 | E45: 0
A46: Total Eaton shareholders' equity | B46: 17038 | C46: 19036 | D46: 18488 | E46: 19425
A47: Noncontrolling interests | B47: 38 | C47: 33 | D47: 43 | E47: 44
...

Sheet Cash Flow
A1: Eaton Corporation (NYSE: ETN): Cash Flow Statement
F3: 1 | G3: 2 | H3: 3 | I3: 4
B4: Historical | F4: Projected
A5: Fiscal year ending Dec 31 ($mm) | B5: 2022A | C5: 2023A | D5: 2024A | E5: 2025A | F5: 2026E | G5: 2027E | H5: 2028E | I5: 2029E | J5: 2030E
A7: Operating activities
A8: Net income | B8: ='Income Statement'!B23 | C8: ='Income Statement'!C23 | D8: ='Income Statement'!D23 | E8: ='Income Statement'!E23 | F8: =E8*(F9+1) | G8: =F8*(G9+1) | H8: =G8*(H9+1) | I8: =H8*(I9+1) | J8: =I8*(J9+1)
C9: =(C8-B8)/B8 | D9: =(D8-C8)/C8 | E9: =(E8-D8)/D8 | F9: =$E$9-($E$9-$J$9)*(F$3/5) | G9: =$E$9-($E$9-$J$9)*(G$3/5) | H9: =$E$9-($E$9-$J$9)*(H$3/5) | I9: =$E$9-($E$9-$J$9)*(I$3/5) | J9: 0.02
A10: Depreciation and amortization | B10: 954 | C10: 926 | D10: 921 | E10: 1006
A11: Deferred income taxes | B11: -128 | C11: -182 | D11: -154 | E11: 45
A12: Pension and other postretirement benefits expense | B12: 54 | C12: 15 | D12: 24 | E12: 43
A13: Contributions to pension plans | B13: -116 | C13: -113 | D13: -110 | E13: -124
A14: Contributions to other postretirement benefits plans | B14: -24 | C14: -20 | D14: -18 | E14: -16
A15: Gain on sale of business | B15: -24 | C15: 0 | D15: 0 | E15: 0
A16: Change in accounts receivable - net | B16: -743 | C16: -341 | D16: -215 | E16: -420
A17: Change in inventory | B17: -490 | C17: -282 | D17: -566 | E17: -256
A18: Change in unbilled receivables | B18: 0 | C18: -54 | D18: -52 | E18: -357
A19: Change in accounts payable | B19: 334 | C19: 256 | D19: 399 | E19: 332
A20: Change in accrued compensation | B20: -16 | C20: 197 | D20: 21 | E20: -50
A21: Change in accrued income and other taxes | B21: 170 | C21: 61 | D21: 142 | E21: -116
... A26: Net cash provided by operating activities | B26: 2533 | C26: 3624 | D26: 4327 | E26: 4472
A28: Investing activities
A29: Capital expenditures | B29: -598 | C29: -757 | D29: -808 | E29: -919 | F29: -1000 | G29: -1100 | H29: -1200 | I29: -1300 | J29: -1400
A30: Acquisitions of businesses, net of cash acquired | B30: -610 | C30: 0 | D30: -50 | E30: -1490
A31: Proceeds from sales of businesses, net | B31: 31 | C31: 0 | D31: 0 | E31: 0
A32: Proceeds from sales of property, plant and equipment | B32: 163 | C32: 76 | D32: 85 | E32: 80
A33: Investments in associate companies | B33: -42 | C33: -68 | D33: -70 | E33: -16
A34: Return of investment from associate companies | B34: 0 | C34: 9 | D34: 33 | E34: 0
A35: Sales (purchases) of short-term investments - net | B35: -19 | C35: -1861 | D35: 575 | E35: 1339
A36: Settlement of currency exchange contracts - net | B36: -47 | C36: 92 | D36: -3 | E36: 3
A37: Other - net | B37: -79 | C37: -65 | D37: -32 | E37: -98
A38: Net cash used in investing activities | B38: -1200 | C38: -2575 | D38: -271 | E38: -1101
A40: Financing activities
A41: Proceeds from borrowings | B41: 1995 | C41: 818 | D41: 1084 | E41: 1058
A42: Payments on borrowings | B42: -2012 | C42: -19 | D42: -1015 | E42: -717
A43: Short-term debt, net | B43: 317 | C43: -311 | D43: -8 | E43: 1
A44: Cash dividends paid | B44: -1299 | C44: -1379 | D44: -1500 | E44: -1626
A45: Exercise of employee stock options | B45: 28 | C45: 78 | D45: 69 | E45: 39
A46: Repurchase of shares | B46: -286 | C46: 0 | D46: -2492 | E46: -1862
A47: Employee taxes paid from shares withheld | B47: -60 | C47: -49 | D47: -70 | E47: -52
A48: Other - net | B48: -23 | C48: -9 | D48: -4 | E48: -14
...
