Workbook

Sheet GEV Quarterly
A1: GE Vernova Inc. (GEV): Quarterly Financials and Segment Data
A2: US$ millions except per-share, unit and percentage data. Blue = taken from the 10-Qs, black = formula. Grey = not in the filings provided. Yellow italic = estimate. Q4 = full year (10-K) less 9M. Notes at the bottom.
A4: Fiscal year | B4: 2024 | C4: 2024 | D4: 2024 | E4: 2024 | F4: 2025 | G4: 2025 | H4: 2025 | I4: 2025 | J4: 2026 | K4: 2026
A5: Quarter | B5: Q1'24 | C5: Q2'24 | D5: Q3'24 | E5: Q4'24 | F5: Q1'25 | G5: Q2'25 | H5: Q3'25 | I5: Q4'25 | J5: Q1'26 | K5: Q2'26
A6: Period end | B6: Mar 31, 2024 | C6: Jun 30, 2024 | D6: Sep 30, 2024 | E6: Dec 31, 2024 | F6: Mar 31, 2025 | G6: Jun 30, 2025 | H6: Sep 30, 2025 | I6: Dec 31, 2025 | J6: Mar 31, 2026 | K6: Jun 30, 2026
A7: Source for income statement, cash flow and segments (latest 10-Q reporting the quarter) | B7: 1Q25 10-Q | C7: 2Q25 10-Q | D7: 3Q25 10-Q | E7: FY24 10-K less 9M | F7: 1Q26 10-Q | G7: 2Q26 10-Q | H7: 3Q25 10-Q | I7: FY25 10-K less 9M | J7: 1Q26 10-Q | K7: 2Q26 10-Q
A9: INCOME STATEMENT
A10: Sales of equipment | B10: 3617 | C10: 4194 | D10: 5290 | E10: =E412-SUM(B10:D10) -> 5851 | F10: 4197 | G10: 4894 | H10: 5880 | I10: =I412-SUM(F10:H10) -> 5963 | J10: 5254 | K10: 6459
A11: Sales of services | B11: 3642 | C11: 4010 | D11: 3623 | E11: =E413-SUM(B11:D11) -> 4708 | F11: 3835 | G11: 4217 | H11: 4089 | I11: =I413-SUM(F11:H11) -> 4993 | J11: 4084 | K11: 4645
A12: Total revenues | B12: 7260 | C12: 8204 | D12: 8913 | E12: =E414-SUM(B12:D12) -> 10558 | F12: 8032 | G12: 9111 | H12: 9969 | I12: =I414-SUM(F12:H12) -> 10956 | J12: 9339 | K12: 11104
A13: Cost of equipment | B13: 3693 | C13: 3853 | D13: 5076 | E13: =E415-SUM(B13:D13) -> 5367 | F13: 3915 | G13: 4265 | H13: 5165 | I13: =I415-SUM(F13:H13) -> 5414 | J13: 4714 | K13: 5613
A14: Cost of services | B14: 2417 | C14: 2649 | D14: 2728 | E14: =E416-SUM(B14:D14) -> 3067 | F14: 2647 | G14: 3000 | H14: 2906 | I14: =I416-SUM(F14:H14) -> 3221 | J14: 2843 | K14: 3130
A15: Gross profit | B15: 1150 | C15: 1702 | D15: 1109 | E15: =E417-SUM(B15:D15) -> 2124 | F15: 1470 | G15: 1846 | H15: 1897 | I15: =I417-SUM(F15:H15) -> 2322 | J15: 1781 | K15: 2360
A16: Selling, general and administrative | B16: 1202 | C16: 938 | D16: 1226 | E16: =E418-SUM(B16:D16) -> 1266 | F16: 1188 | G16: 1185 | H16: 1221 | I16: =I418-SUM(F16:H16) -> 1355 | J16: 1298 | K16: 1372
A17: Research and development | B17: 237 | C17: 237 | D17: 243 | E17: =E419-SUM(B17:D17) -> 265 | F17: 239 | G17: 282 | H17: 310 | I17: =I419-SUM(F17:H17) -> 366 | J17: 304 | K17: 334
A18: Operating income (loss) | B18: -289 | C18: 527 | D18: -359 | E18: =E420-SUM(B18:D18) -> 592 | F18: 43 | G18: 378 | H18: 366 | I18: =I420-SUM(F18:H18) -> 601 | J18: 179 | K18: 653
A19: Interest and other financial income (charges), net | B19: -14 | C19: 60 | D19: 36 | E19: =E421-SUM(B19:D19) -> 38 | F19: 56 | G19: 42 | H19: 44 | I19: =I421-SUM(F19:H19) -> 44 | J19: 28 | K19: 73
A20: Non-operating benefit income | B20: 134 | C20: 134 | D20: 130 | E20: =E422-SUM(B20:D20) -> 138 | F20: 115 | G20: 110 | H20: 115 | I20: =I422-SUM(F20:H20) -> 119 | J20: 134 | K20: 119
A21: Other income (expense), net | B21: 73 | C21: 881 | D21: 71 | E21: =E423-SUM(B21:D21) -> 347 | F21: 119 | G21: 115 | H21: 221 | I21: =I423-SUM(F21:H21) -> 340 | J21: 4762 | K21: 80
... A26: Net income (loss) attributable to GE Vernova | B26: -130 | C26: 1294 | D26: -96 | E26: =E428-SUM(B26:D26) -> 484 | F26: 254 | G26: 514 | H26: 452 | I26: =I428-SUM(F26:H26) -> 3664 | J26: 4745 | K26: 668
A27: EPS, basic ($) | B27: -0.47 | C27: 4.72 | D27: -0.35 | E27: =E26/E29 -> 1.7472924 | F27: 0.92 | G27: 1.89 | H27: 1.66 | I27: =I26/I29 -> 13.620818 | J27: 17.65 | K27: 2.49
A28: EPS, diluted ($) | B28: -0.47 | C28: 4.65 | D28: -0.35 | E28: =E26/E30 -> 1.6982456 | F28: 0.91 | G28: 1.86 | H28: 1.64 | I28: =I26/I30 -> 13.372263 | J28: 17.44 | K28: 2.47
A29: Weighted-avg shares, basic (mm) | B29: 274 | C29: 274 | D29: 275 | E29: =4*E429-SUM(B29:D29) -> 277 | F29: 275 | G29: 272 | H29: 272 | I29: =4*I429-SUM(F29:H29) -> 269 | J29: 269 | K29: 268
A30: Weighted-avg shares, diluted (mm) | B30: 274 | C30: 278 | D30: 275 | E30: =4*E430-SUM(B30:D30) -> 285 | F30: 279 | G30: 276 | H30: 275 | I30: =4*I430-SUM(F30:H30) -> 274 | J30: 272 | K30: 270
A32: GROWTH AND MARGINS
A33: Total revenue growth, YoY | F33: =IF(AND(ISNUMBER(F12),ISNUMBER(B12),B12<>0),F12/B12-1,"") -> 0.10633609 | G33: =IF(AND(ISNUMBER(G12),ISNUMBER(C12),C12<>0),G12/C12-1,"") -> 0.11055583 | H33: =IF(AND(ISNUMBER(H12),ISNUMBER(D12),D12<>0),H12/D12-1,"") -> 0.11847863 | I33: =IF(AND(ISNUMBER(I12),ISNUMBER(E12),E12<>0),I12/E12-1,"") -> 0.037696533 | J33: =IF(AND(ISNUMBER(J12),ISNUMBER(F12),F12<>0),J12/F12-1,"") -> 0.1627241 | K33: =IF(AND(ISNUMBER(K12),ISNUMBER(G12),G12<>0),K12/G12-1,"") -> 0.21874657
A34: Equipment revenue growth, YoY | F34: =IF(AND(ISNUMBER(F10),ISNUMBER(B10),B10<>0),F10/B10-1,"") -> 0.16035388 | G34: =IF(AND(ISNUMBER(G10),ISNUMBER(C10),C10<>0),G10/C10-1,"") -> 0.1669051 | H34: =IF(AND(ISNUMBER(H10),ISNUMBER(D10),D10<>0),H10/D10-1,"") -> 0.11153119 | I34: =IF(AND(ISNUMBER(I10),ISNUMBER(E10),E10<>0),I10/E10-1,"") -> 0.019142027 | J34: =IF(AND(ISNUMBER(J10),ISNUMBER(F10),F10<>0),J10/F10-1,"") -> 0.25184656 | K34: =IF(AND(ISNUMBER(K10),ISNUMBER(G10),G10<>0),K10/G10-1,"") -> 0.31977932
A35: Services revenue growth, YoY | F35: =IF(AND(ISNUMBER(F11),ISNUMBER(B11),B11<>0),F11/B11-1,"") -> 0.052992861 | G35: =IF(AND(ISNUMBER(G11),ISNUMBER(C11),C11<>0),G11/C11-1,"") -> 0.051620948 | H35: =IF(AND(ISNUMBER(H11),ISNUMBER(D11),D11<>0),H11/D11-1,"") -> 0.12862269 | I35: =IF(AND(ISNUMBER(I11),ISNUMBER(E11),E11<>0),I11/E11-1,"") -> 0.060535259 | J35: =IF(AND(ISNUMBER(J11),ISNUMBER(F11),F11<>0),J11/F11-1,"") -> 0.064928292 | K35: =IF(AND(ISNUMBER(K11),ISNUMBER(G11),G11<>0),K11/G11-1,"") -> 0.10149395
A36: Gross margin | B36: =IF(AND(ISNUMBER(B15),ISNUMBER(B12),B12<>0),B15/B12,"") -> 0.1584022 | C36: =IF(AND(ISNUMBER(C15),ISNUMBER(C12),C12<>0),C15/C12,"") -> 0.20745978 | D36: =IF(AND(ISNUMBER(D15),ISNUMBER(D12),D12<>0),D15/D12,"") -> 0.124425 | E36: =IF(AND(ISNUMBER(E15),ISNUMBER(E12),E12<>0),E15/E12,"") -> 0.20117446 | F36: =IF(AND(ISNUMBER(F15),ISNUMBER(F12),F12<>0),F15/F12,"") -> 0.18301793 | G36: =IF(AND(ISNUMBER(G15),ISNUMBER(G12),G12<>0),G15/G12,"") -> 0.20261223 | H36: =IF(AND(ISNUMBER(H15),ISNUMBER(H12),H12<>0),H15/H12,"") -> 0.1902899 | I36: =IF(AND(ISNUMBER(I15),ISNUMBER(I12),I12<>0),I15/I12,"") -> 0.21193866 | ... K36: =IF(AND(ISNUMBER(K15),ISNUMBER(K12),K12<>0),K15/K12,"") -> 0.21253602
A37: Equipment gross margin | B37: =IF(ISNUMBER(B10),(B10-B13)/B10,"") -> -0.021011888 | C37: =IF(ISNUMBER(C10),(C10-C13)/C10,"") -> 0.081306629 | D37: =IF(ISNUMBER(D10),(D10-D13)/D10,"") -> 0.040453686 | E37: =IF(ISNUMBER(E10),(E10-E13)/E10,"") -> 0.082720902 | F37: =IF(ISNUMBER(F10),(F10-F13)/F10,"") -> 0.067190851 | G37: =IF(ISNUMBER(G10),(G10-G13)/G10,"") -> 0.12852472 | H37: =IF(ISNUMBER(H10),(H10-H13)/H10,"") -> 0.12159864 | I37: =IF(ISNUMBER(I10),(I10-I13)/I10,"") -> 0.092067751 | ... K37: =IF(ISNUMBER(K10),(K10-K13)/K10,"") -> 0.13098003
A38: Services gross margin | B38: =IF(ISNUMBER(B11),(B11-B14)/B11,"") -> 0.33635365 | C38: =IF(ISNUMBER(C11),(C11-C14)/C11,"") -> 0.3394015 | D38: =IF(ISNUMBER(D11),(D11-D14)/D11,"") -> 0.24703285 | E38: =IF(ISNUMBER(E11),(E11-E14)/E11,"") -> 0.34855565 | F38: =IF(ISNUMBER(F11),(F11-F14)/F11,"") -> 0.30977836 | G38: =IF(ISNUMBER(G11),(G11-G14)/G11,"") -> 0.28859379 | H38: =IF(ISNUMBER(H11),(H11-H14)/H11,"") -> 0.28931279 | I38: =IF(ISNUMBER(I11),(I11-I14)/I11,"") -> 0.35489686 | ... K38: =IF(ISNUMBER(K11),(K11-K14)/K11,"") -> 0.32615716
A39: SG&A as % of revenue | B39: =IF(AND(ISNUMBER(B16),ISNUMBER(B12),B12<>0),B16/B12,"") -> 0.16556474 | C39: =IF(AND(ISNUMBER(C16),ISNUMBER(C12),C12<>0),C16/C12,"") -> 0.11433447 | D39: =IF(AND(ISNUMBER(D16),ISNUMBER(D12),D12<>0),D16/D12,"") -> 0.13755189 | E39: =IF(AND(ISNUMBER(E16),ISNUMBER(E12),E12<>0),E16/E12,"") -> 0.11990907 | F39: =IF(AND(ISNUMBER(F16),ISNUMBER(F12),F12<>0),F16/F12,"") -> 0.14790837 | G39: =IF(AND(ISNUMBER(G16),ISNUMBER(G12),G12<>0),G16/G12,"") -> 0.13006256 | H39: =IF(AND(ISNUMBER(H16),ISNUMBER(H12),H12<>0),H16/H12,"") -> 0.12247969 | I39: =IF(AND(ISNUMBER(I16),ISNUMBER(I12),I12<>0),I16/I12,"") -> 0.12367652 | ... K39: =IF(AND(ISNUMBER(K16),ISNUMBER(K12),K12<>0),K16/K12,"") -> 0.12355908
A40: R&D as % of revenue | B40: =IF(AND(ISNUMBER(B17),ISNUMBER(B12),B12<>0),B17/B12,"") -> 0.032644628 | C40: =IF(AND(ISNUMBER(C17),ISNUMBER(C12),C12<>0),C17/C12,"") -> 0.028888347 | D40: =IF(AND(ISNUMBER(D17),ISNUMBER(D12),D12<>0),D17/D12,"") -> 0.027263548 | E40: =IF(AND(ISNUMBER(E17),ISNUMBER(E12),E12<>0),E17/E12,"") -> 0.025099451 | F40: =IF(AND(ISNUMBER(F17),ISNUMBER(F12),F12<>0),F17/F12,"") -> 0.029755976 | G40: =IF(AND(ISNUMBER(G17),ISNUMBER(G12),G12<>0),G17/G12,"") -> 0.030951597 | H40: =IF(AND(ISNUMBER(H17),ISNUMBER(H12),H12<>0),H17/H12,"") -> 0.031096399 | I40: =IF(AND(ISNUMBER(I17),ISNUMBER(I12),I12<>0),I17/I12,"") -> 0.033406353 | ... K40: =IF(AND(ISNUMBER(K17),ISNUMBER(K12),K12<>0),K17/K12,"") -> 0.030079251
A41: Operating margin | B41: =IF(AND(ISNUMBER(B18),ISNUMBER(B12),B12<>0),B18/B12,"") -> -0.039807163 | C41: =IF(AND(ISNUMBER(C18),ISNUMBER(C12),C12<>0),C18/C12,"") -> 0.064236958 | D41: =IF(AND(ISNUMBER(D18),ISNUMBER(D12),D12<>0),D18/D12,"") -> -0.040278245 | E41: =IF(AND(ISNUMBER(E18),ISNUMBER(E12),E12<>0),E18/E12,"") -> 0.056071226 | F41: =IF(AND(ISNUMBER(F18),ISNUMBER(F12),F12<>0),F18/F12,"") -> 0.0053535857 | G41: =IF(AND(ISNUMBER(G18),ISNUMBER(G12),G12<>0),G18/G12,"") -> 0.041488311 | H41: =IF(AND(ISNUMBER(H18),ISNUMBER(H12),H12<>0),H18/H12,"") -> 0.036713813 | I41: =IF(AND(ISNUMBER(I18),ISNUMBER(I12),I12<>0),I18/I12,"") -> 0.054855787 | ... K41: =IF(AND(ISNUMBER(K18),ISNUMBER(K12),K12<>0),K18/K12,"") -> 0.058807637
A42: Pre-tax income excl. other income (expense) | B42: =B18+B19+B20 -> -169 | C42: =C18+C19+C20 -> 721 | D42: =D18+D19+D20 -> -193 | E42: =E18+E19+E20 -> 768 | F42: =F18+F19+F20 -> 214 | G42: =G18+G19+G20 -> 530 | H42: =H18+H19+H20 -> 525 | I42: =I18+I19+I20 -> 764 | ... K42: =K18+K19+K20 -> 845
A43: Net margin (attributable to GE Vernova) | B43: =IF(AND(ISNUMBER(B26),ISNUMBER(B12),B12<>0),B26/B12,"") -> -0.017906336 | C43: =IF(AND(ISNUMBER(C26),ISNUMBER(C12),C12<>0),C26/C12,"") -> 0.15772794 | D43: =IF(AND(ISNUMBER(D26),ISNUMBER(D12),D12<>0),D26/D12,"") -> -0.010770784 | E43: =IF(AND(ISNUMBER(E26),ISNUMBER(E12),E12<>0),E26/E12,"") -> 0.045842016 | F43: =IF(AND(ISNUMBER(F26),ISNUMBER(F12),F12<>0),F26/F12,"") -> 0.031623506 | G43: =IF(AND(ISNUMBER(G26),ISNUMBER(G12),G12<>0),G26/G12,"") -> 0.056415322 | H43: =IF(AND(ISNUMBER(H26),ISNUMBER(H12),H12<>0),H26/H12,"") -> 0.045340556 | I43: =IF(AND(ISNUMBER(I26),ISNUMBER(I12),I12<>0),I26/I12,"") -> 0.33442862 | ... K43: =IF(AND(ISNUMBER(K26),ISNUMBER(K12),K12<>0),K26/K12,"") -> 0.060158501
A44: Effective tax rate (blank when pre-tax income is negative) | B44: =IF(AND(ISNUMBER(B22),B22>0),B23/B22,"") | C44: =IF(AND(ISNUMBER(C22),C22>0),C23/C22,"") -> 0.20099875 | D44: =IF(AND(ISNUMBER(D22),D22>0),D23/D22,"") | E44: =IF(AND(ISNUMBER(E22),E22>0),E23/E22,"") -> 0.56552962 | F44: =IF(AND(ISNUMBER(F22),F22>0),F23/F22,"") -> 0.20481928 | G44: =IF(AND(ISNUMBER(G22),G22>0),G23/G22,"") -> 0.2372093 | H44: =IF(AND(ISNUMBER(H22),H22>0),H23/H22,"") -> 0.39276139 | I44: =IF(AND(ISNUMBER(I22),I22>0),I23/I22,"") -> -2.321267 | ... K44: =IF(AND(ISNUMBER(K22),K22>0),K23/K22,"") -> 0.29837838
A45: Adjusted EBITDA margin (company-defined) | B45: =IF(ISNUMBER(B57),B57/B12,"") -> 0.026033058 | C45: =IF(ISNUMBER(C57),C57/C12,"") -> 0.063871282 | D45: =IF(ISNUMBER(D57),D57/D12,"") -> 0.027263548 | E45: =IF(ISNUMBER(E57),E57/E12,"") -> 0.10219739 | F45: =IF(ISNUMBER(F57),F57/F12,"") -> 0.05689741 | G45: =IF(ISNUMBER(G57),G57/G12,"") -> 0.084513226 | H45: =IF(ISNUMBER(H57),H57/H12,"") -> 0.081352192 | I45: =IF(ISNUMBER(I57),I57/I12,"") -> 0.10569551 | ... K45: =IF(ISNUMBER(K57),K57/K12,"") -> 0.11257205
A47: ADJUSTED EBITDA BRIDGE (company non-GAAP, three months)
A48: Net income (loss), GAAP | B48: =B293 -> -106 | C48: =C293 -> 1280 | D48: =D293 -> -99 | E48: =E293 -> 484 | F48: =F293 -> 264 | G48: =G293 -> 492 | H48: =H293 -> 453 | I48: =I293 -> 3670 | ... K48: =K293 -> 648
...

Sheet Sheet1
A1: GEV Revenue Segmentation
A2: We assume that the percent of segmentation is delegated uniformaly throughout the annualized year.
B3: Historical | M3: Projected
B4: Fiscal year | C4: 2024 | D4: 2024 | E4: 2024 | F4: 2024 | G4: 2025 | H4: 2025 | I4: 2025 | J4: 2025 | K4: 2026 | L4: 2026 | M4: 2026 | N4: 2026
B5: Quarter | C5: Q1'24 | D5: Q2'24 | E5: Q3'24 | F5: Q4'24 | G5: Q1'25 | H5: Q2'25 | I5: Q3'25 | J5: Q4'25 | K5: Q1'26 | L5: Q2'26 | M5: Q3'26 | N5: Q4'26
B6: Segment basis | C6: Legacy | D6: Legacy | E6: Legacy | F6: Legacy | G6: Legacy | H6: Legacy | I6: Legacy | J6: Legacy | K6: Current | L6: Current
B8: Segment Revenue Summary (US$ millions)
B9: Wind | C9: =C37 -> 1639 | D9: =D37 -> 2062 | E9: =E37 -> 2891 | F9: =F37 -> 3109 | G9: =G37 -> 1850 | H9: =H37 -> 2245 | I9: =I37 -> 2647 | J9: =J37 -> 2368 | ... L9: =L37 -> 2026
B10: Electrification | C10: =C74 -> 1651 | D10: =D74 -> 1790 | E10: =E74 -> 1928 | F10: =F74 -> 2181 | G10: =G74 -> 1879 | H10: =H74 -> 2201 | I10: =I74 -> 2601 | J10: =J74 -> 2961 | ... L10: =L74 -> 3637
B11: Power | C11: =C111 -> 4035 | D11: =D111 -> 4455 | E11: =E111 -> 4206 | F11: =F111 -> 5431 | G11: =G111 -> 4423 | H11: =H111 -> 4758 | I11: =I111 -> 4838 | J11: =J111 -> 5748 | ... L11: =L111 -> 5477
B12: Eliminations and other | C12: ='GEV Quarterly'!B112 -> -65 | D12: ='GEV Quarterly'!C112 -> -103 | E12: ='GEV Quarterly'!D112 -> -112 | F12: ='GEV Quarterly'!E112 -> -162 | G12: ='GEV Quarterly'!F112 -> -119 | H12: ='GEV Quarterly'!G112 -> -92 | I12: ='GEV Quarterly'!H112 -> -119 | J12: ='GEV Quarterly'!I112 -> -121 | K12: ='GEV Quarterly'!J164 -> -25 | L12: ='GEV Quarterly'!K164 -> -37
B13: Total revenues | C13: =SUM(C9:C12) -> 7260 | D13: =SUM(D9:D12) -> 8204 | E13: =SUM(E9:E12) -> 8913 | F13: =SUM(F9:F12) -> 10559 | G13: =SUM(G9:G12) -> 8033 | H13: =SUM(H9:H12) -> 9112 | I13: =SUM(I9:I12) -> 9967 | J13: =SUM(J9:J12) -> 10956 | ... L13: =SUM(L9:L12) -> 11103
B14: Check: total less income statement revenue (rounding only) | C14: =C13-'GEV Quarterly'!B12 -> 0 | D14: =D13-'GEV Quarterly'!C12 -> 0 | E14: =E13-'GEV Quarterly'!D12 -> 0 | F14: =F13-'GEV Quarterly'!E12 -> 1 | G14: =G13-'GEV Quarterly'!F12 -> 1 | H14: =H13-'GEV Quarterly'!G12 -> 1 | I14: =I13-'GEV Quarterly'!H12 -> -2 | J14: =J13-'GEV Quarterly'!I12 -> 0 | ... L14: =L13-'GEV Quarterly'!K12 -> -1
B16: Revenue growth, YoY (%)
B17: Wind | G17: =IF(C9<>0,G9/C9-1,"") -> 0.12873703 | H17: =IF(D9<>0,H9/D9-1,"") -> 0.088748788 | I17: =IF(E9<>0,I9/E9-1,"") -> -0.084399862 | J17: =IF(F9<>0,J9/F9-1,"") -> -0.2383403 | K17: =K9/'GEV Quarterly'!F163-1 -> -0.22594595 | L17: =L9/'GEV Quarterly'!G163-1 -> -0.097550111
B18: Electrification | G18: =IF(C10<>0,G10/C10-1,"") -> 0.13809812 | H18: =IF(D10<>0,H10/D10-1,"") -> 0.22960894 | I18: =IF(E10<>0,I10/E10-1,"") -> 0.34906639 | J18: =IF(F10<>0,J10/F10-1,"") -> 0.35763411 | K18: =K10/'GEV Quarterly'!F162-1 -> 0.60815217 | L18: =L10/'GEV Quarterly'!G162-1 -> 0.68223867
B19: Power | G19: =IF(C11<>0,G11/C11-1,"") -> 0.096158612 | H19: =IF(D11<>0,H11/D11-1,"") -> 0.068013468 | I19: =IF(E11<>0,I11/E11-1,"") -> 0.15026153 | J19: =IF(F11<>0,J11/F11-1,"") -> 0.058368625 | K19: =K11/'GEV Quarterly'!F161-1 -> 0.11732974 | L19: =L11/'GEV Quarterly'!G161-1 -> 0.1446186
B20: Total revenues | G20: =IF(C13<>0,G13/C13-1,"") -> 0.10647383 | H20: =IF(D13<>0,H13/D13-1,"") -> 0.11067772 | I20: =IF(E13<>0,I13/E13-1,"") -> 0.11825424 | J20: =IF(F13<>0,J13/F13-1,"") -> 0.037598257 | K20: =IF(G13<>0,K13/G13-1,"") -> 0.16233039 | L20: =IF(H13<>0,L13/H13-1,"") -> 0.21850307
B22: Ending RPO (US$ millions)
B23: Wind | C23: =C39 -> 26164 | D23: =D39 -> 25773 | E23: =E39 -> 24969 | F23: =F39 -> 22682 | G23: =G39 -> 22160 | H23: =H39 -> 22508 | I23: =I39 -> 21508 | J23: =J39 -> 21630 | ... L23: =L39 -> 20388
B24: Electrification | C24: =C76 -> 18069 | D24: =D76 -> 20679 | E24: =E76 -> 21912 | F24: =F76 -> 23453 | G24: =G76 -> 25462 | H24: =H76 -> 27530 | I24: =I76 -> 30179 | J24: =J76 -> 34667 | ... L24: =L76 -> 44563
B25: Power | C25: =C113 -> 72783 | D25: =D113 -> 69457 | E25: =E113 -> 71303 | F25: =F113 -> 73351 | G25: =G113 -> 76292 | H25: =H113 -> 79065 | I25: =I113 -> 84060 | J25: =J113 -> 94387 | ... L25: =L113 -> 111649
B26: Eliminations and other (derived) | C26: =C27-SUM(C23:C25) -> -723 | D26: =D27-SUM(D23:D25) -> -433 | E26: =E27-SUM(E23:E25) -> -438 | F26: =F27-SUM(F23:F25) -> -463 | G26: =G27-SUM(G23:G25) -> -476 | H26: =H27-SUM(H23:H25) -> -453 | I26: =I27-SUM(I23:I25) -> -478 | J26: =J27-SUM(J23:J25) -> -446 | ... L26: =L27-SUM(L23:L25) -> -316
B27: Total RPO (consolidated, as reported) | C27: ='GEV Quarterly'!B214 -> 116293 | D27: ='GEV Quarterly'!C214 -> 115476 | E27: ='GEV Quarterly'!D214 -> 117746 | F27: ='GEV Quarterly'!E214 -> 119023 | G27: ='GEV Quarterly'!F214 -> 123438 | H27: ='GEV Quarterly'!G214 -> 128650 | I27: ='GEV Quarterly'!H214 -> 135269 | J27: ='GEV Quarterly'!I214 -> 150238 | ... L27: ='GEV Quarterly'!K214 -> 176284
B28: Equipment RPO (consolidated) | C28: ='GEV Quarterly'!B212 -> 42210 | D28: ='GEV Quarterly'!C212 -> 41561 | E28: ='GEV Quarterly'!D212 -> 42069 | F28: ='GEV Quarterly'!E212 -> 43047 | G28: ='GEV Quarterly'!F212 -> 45478 | H28: ='GEV Quarterly'!G212 -> 49712 | I28: ='GEV Quarterly'!H212 -> 54092 | J28: ='GEV Quarterly'!I212 -> 64245 | ... L28: ='GEV Quarterly'!K212 -> 87821
B29: Services RPO (consolidated) | C29: ='GEV Quarterly'!B213 -> 74083 | D29: ='GEV Quarterly'!C213 -> 73915 | E29: ='GEV Quarterly'!D213 -> 75678 | F29: ='GEV Quarterly'!E213 -> 75976 | G29: ='GEV Quarterly'!F213 -> 77959 | H29: ='GEV Quarterly'!G213 -> 78938 | I29: ='GEV Quarterly'!H213 -> 81177 | J29: ='GEV Quarterly'!I213 -> 85993 | ... L29: ='GEV Quarterly'!K213 -> 88463
B31: Segment Revenue Build: RPO Roll-Forward (US$ millions)
B33: Wind
B34: Beginning RPO: | D34: =C39 -> 26164 | E34: =D39 -> 25773 | F34: =E39 -> 24969 | G34: =F39 -> 22682 | H34: =G39 -> 22160 | I34: =H39 -> 22508 | J34: =I39 -> 21508 | K34: =J39 -> 21630 | L34: =K39 -> 21348
B35: (+/-) Segment realignment | K35: ='GEV Quarterly'!I246-'GEV Quarterly'!I233 -> 0
B36: (+) Orders (implied) | D36: ='GEV Quarterly'!C234 -> 1671 | E36: ='GEV Quarterly'!D234 -> 2087 | F36: ='GEV Quarterly'!E234 -> 822 | G36: ='GEV Quarterly'!F234 -> 1328 | H36: ='GEV Quarterly'!G234 -> 2593 | I36: ='GEV Quarterly'!H234 -> 1647 | J36: ='GEV Quarterly'!I234 -> 2490 | K36: ='GEV Quarterly'!J247 -> 1150 | L36: ='GEV Quarterly'!K247 -> 1066
B37: (-) Revenue | C37: ='GEV Quarterly'!B111 -> 1639 | D37: ='GEV Quarterly'!C111 -> 2062 | E37: ='GEV Quarterly'!D111 -> 2891 | F37: ='GEV Quarterly'!E111 -> 3109 | G37: ='GEV Quarterly'!F111 -> 1850 | H37: ='GEV Quarterly'!G111 -> 2245 | I37: ='GEV Quarterly'!H111 -> 2647 | J37: ='GEV Quarterly'!I111 -> 2368 | K37: ='GEV Quarterly'!J163 -> 1432 | L37: ='GEV Quarterly'!K163 -> 2026
B38: (%) of RPO conversion | D38: =IF((D34+D35)<>0,D37/(D34+D35),"") -> 0.078810579 | E38: =IF((E34+E35)<>0,E37/(E34+E35),"") -> 0.11217165 | F38: =IF((F34+F35)<>0,F37/(F34+F35),"") -> 0.1245144 | G38: =IF((G34+G35)<>0,G37/(G34+G35),"") -> 0.081562472 | H38: =IF((H34+H35)<>0,H37/(H34+H35),"") -> 0.10130866 | I38: =IF((I34+I35)<>0,I37/(I34+I35),"") -> 0.11760263 | J38: =IF((J34+J35)<>0,J37/(J34+J35),"") -> 0.11009857 | K38: =IF((K34+K35)<>0,K37/(K34+K35),"") -> 0.066204346 | L38: =IF((L34+L35)<>0,L37/(L34+L35),"") -> 0.094903504
B39: Ending Backlog | C39: ='GEV Quarterly'!B233 -> 26164 | D39: =D34+D35+D36-D37 -> 25773 | E39: =E34+E35+E36-E37 -> 24969 | F39: =F34+F35+F36-F37 -> 22682 | G39: =G34+G35+G36-G37 -> 22160 | H39: =H34+H35+H36-H37 -> 22508 | I39: =I34+I35+I36-I37 -> 21508 | J39: =J34+J35+J36-J37 -> 21630 | K39: =K34+K35+K36-K37 -> 21348 | L39: =L34+L35+L36-L37 -> 20388
B41: Equipment
B42: Beginning RPO: | D42: =C47 -> 13119 | E42: =D47 -> 13147 | F42: =E47 -> 12182 | G42: =F47 -> 10720 | H42: =G47 -> 9676 | I42: =H47 -> 9731 | J42: =I47 -> 8782 | K42: =J47 -> 9112 | L42: =K47 -> 8905
B43: (+/-) Segment realignment | K43: ='GEV Quarterly'!I244-'GEV Quarterly'!I231 -> 0
B44: (+) Orders (implied) | D44: ='GEV Quarterly'!C231-'GEV Quarterly'!B231+'GEV Quarterly'!C149 -> 1696 | E44: ='GEV Quarterly'!D231-'GEV Quarterly'!C231+'GEV Quarterly'!D149 -> 1529 | F44: ='GEV Quarterly'!E231-'GEV Quarterly'!D231+'GEV Quarterly'!E149 -> 1191 | G44: ='GEV Quarterly'!F231-'GEV Quarterly'!E231+'GEV Quarterly'!F149 -> 368 | H44: ='GEV Quarterly'!G231-'GEV Quarterly'!F231+'GEV Quarterly'!G149 -> 1852 | I44: ='GEV Quarterly'!H231-'GEV Quarterly'!G231+'GEV Quarterly'!H149 -> 1254 | J44: ='GEV Quarterly'!I231-'GEV Quarterly'!H231+'GEV Quarterly'!I149 -> 2169 | K44: ='GEV Quarterly'!J244-'GEV Quarterly'!I244+'GEV Quarterly'!J201 -> 682 | L44: ='GEV Quarterly'!K244-'GEV Quarterly'!J244+'GEV Quarterly'!K201 -> 687
B45: (-) Revenue | C45: ='GEV Quarterly'!B149 -> 1232 | D45: ='GEV Quarterly'!C149 -> 1668 | E45: ='GEV Quarterly'!D149 -> 2494 | F45: ='GEV Quarterly'!E149 -> 2653 | G45: ='GEV Quarterly'!F149 -> 1412 | H45: ='GEV Quarterly'!G149 -> 1797 | I45: ='GEV Quarterly'!H149 -> 2203 | J45: ='GEV Quarterly'!I149 -> 1839 | K45: ='GEV Quarterly'!J201 -> 889 | L45: ='GEV Quarterly'!K201 -> 1395
B46: (%) of RPO conversion | D46: =IF((D42+D43)<>0,D45/(D42+D43),"") -> 0.12714384 | E46: =IF((E42+E43)<>0,E45/(E42+E43),"") -> 0.18970107 | F46: =IF((F42+F43)<>0,F45/(F42+F43),"") -> 0.21778033 | G46: =IF((G42+G43)<>0,G45/(G42+G43),"") -> 0.13171642 | H46: =IF((H42+H43)<>0,H45/(H42+H43),"") -> 0.18571724 | I46: =IF((I42+I43)<>0,I45/(I42+I43),"") -> 0.22638989 | J46: =IF((J42+J43)<>0,J45/(J42+J43),"") -> 0.2094056 | K46: =IF((K42+K43)<>0,K45/(K42+K43),"") -> 0.097563652 | L46: =IF((L42+L43)<>0,L45/(L42+L43),"") -> 0.15665357
...

Sheet Revenue
C2: GE Vernova (GEV)
C3: Revenue build, quarterly
C4: US$ millions unless stated. Blue = input, black = formula, orange = assumption, grey = projection. Annual columns add up the quarters.
C5: Scenario | D5: ='Key Drivers'!D5 -> Base | E5: Change on 'Key Drivers'
F6: Annual: historical | H6: Annual: projected | N6: Quarterly: historical | X6: Quarterly: projected
C7: Fiscal period | D7: Unit | E7: Note | F7: FY2024A | G7: FY2025A | H7: FY2026E | I7: FY2027E | J7: FY2028E | K7: FY2029E | L7: FY2030E | N7: Q1'24 | O7: Q2'24 | P7: Q3'24 | Q7: Q4'24 | R7: Q1'25 | S7: Q2'25 | T7: Q3'25 | U7: Q4'25 | V7: Q1'26 | W7: Q2'26 | X7: Q3'26 | Y7: Q4'26 | Z7: Q1'27 | AA7: Q2'27 | AB7: Q3'27 | AC7: Q4'27 | AD7: Q1'28 | AE7: Q2'28 | AF7: Q3'28 | AG7: Q4'28 | AH7: Q1'29 | AI7: Q2'29 | AJ7: Q3'29 | AK7: Q4'29 | AL7: Q1'30 | AM7: Q2'30 | AN7: Q3'30 | AO7: Q4'30
C8: Period end | F8: 45657 | G8: 46022 | H8: 46387 | I8: 46752 | J8: 47118 | K8: 47483 | L8: 47848 | N8: 45382 | O8: 45473 | P8: 45565 | Q8: 45657 | R8: 45747 | S8: 45838 | T8: 45930 | U8: 46022 | V8: 46112 | W8: 46203 | X8: 46295 | Y8: 46387 | Z8: 46477 | AA8: 46568 | AB8: 46660 | AC8: 46752 | AD8: 46843 | AE8: 46934 | AF8: 47026 | AG8: 47118 | AH8: 47208 | AI8: 47299 | AJ8: 47391 | AK8: 47483 | AL8: 47573 | AM8: 47664 | AN8: 47756 | AO8: 47848
C10: Revenue summary
C11: Power: equipment (gas turbine led) | E11: Gas GW shipped x revenue per GW | F11: =F69 -> 5708 | G11: =G69 -> 6686 | H11: =H69 -> 9347.4304 | I11: =I69 -> 12605.151 | J11: =J69 -> 14675.73 | K11: =K69 -> 16934.498 | L11: =L69 -> 19222.087 | N11: =N69 -> 1201 | O11: =O69 -> 1285 | P11: =P69 -> 1426 | Q11: =Q69 -> 1796 | R11: =R69 -> 1491 | S11: =S69 -> 1504 | T11: =T69 -> 1744 | U11: =U69 -> 1947 | ... AO11: =AO69 -> 5034.3573
C12: Power: services | E12: Installed-base growth | F12: =F73 -> 12525 | G12: =G73 -> 13187 | H12: =H73 -> 14032.36 | I12: =I73 -> 14733.978 | J12: =J73 -> 15397.007 | K12: =K73 -> 16012.887 | L12: =L73 -> 16653.403 | N12: =N73 -> 2860.5 | O12: =O73 -> 3196.5 | P12: =P73 -> 2806.5 | Q12: =Q73 -> 3661.5 | R12: =R73 -> 2958 | S12: =S73 -> 3281 | T12: =T73 -> 3120.5 | U12: =U73 -> 3827.5 | ... AO12: =AO73 -> 4860.3914
C13: Electrification: equipment | E13: Backlog conversion; data-centre orders | F13: =F91 -> 5534 | G13: =G91 -> 7378 | H13: =H91 -> 12631.042 | I13: =I91 -> 14584.605 | J13: =J91 -> 16832.977 | K13: =K91 -> 18984.914 | L13: =L91 -> 20935.524 | N13: =N91 -> 1230 | O13: =O91 -> 1286 | P13: =P91 -> 1451 | Q13: =Q91 -> 1567 | R13: =R91 -> 1391 | S13: =S91 -> 1673 | T13: =T91 -> 2035 | U13: =U91 -> 2279 | ... AO13: =AO91 -> 5549.3515
C14: Electrification: services | F14: =F98 -> 1860 | G14: =G98 -> 2108 | H14: =H98 -> 2181.8 | I14: =I98 -> 2290.89 | J14: =J98 -> 2405.4345 | K14: =K98 -> 2525.7062 | L14: =L98 -> 2651.9915 | N14: =N98 -> 382 | O14: =O98 -> 465 | P14: =P98 -> 438 | Q14: =Q98 -> 575 | R14: =R98 -> 449 | S14: =S98 -> 489 | T14: =T98 -> 527 | U14: =U98 -> 643 | ... AO14: =AO98 -> 812.83334
C15: Wind: equipment | E15: GW shipped x revenue per GW | F15: =F105 -> 8047 | G15: =G105 -> 7251 | H15: =H105 -> 5641.5283 | I15: =I105 -> 4408.4346 | J15: =J105 -> 3881.6832 | K15: =K105 -> 3689.8824 | L15: =L105 -> 3726.7812 | N15: =N105 -> 1232 | O15: =O105 -> 1668 | P15: =P105 -> 2494 | Q15: =Q105 -> 2653 | R15: =R105 -> 1412 | S15: =S105 -> 1797 | T15: =T105 -> 2203 | U15: =U105 -> 1839 | ... AO15: =AO105 -> 1043.4987
C16: Wind: services | F16: =F107 -> 1654 | G16: =G107 -> 1859 | H16: =H107 -> 2390.25 | I16: =I107 -> 2485.86 | J16: =J107 -> 2560.4358 | K16: =K107 -> 2637.2489 | L16: =L107 -> 2716.3663 | N16: =N107 -> 407 | O16: =O107 -> 394 | P16: =P107 -> 397 | Q16: =Q107 -> 456 | R16: =R107 -> 438 | S16: =S107 -> 448 | T16: =T107 -> 444 | U16: =U107 -> 529 | ... AO16: =AO107 -> 751.46836
C17: Eliminations and other | F17: =SUM(N17:Q17) -> -393 | G17: =SUM(R17:U17) -> -400 | H17: =SUM(V17:Y17) -> -190.61205 | I17: =SUM(Z17:AC17) -> -255.54459 | J17: =SUM(AD17:AG17) -> -278.76634 | K17: =SUM(AH17:AK17) -> -303.92569 | L17: =SUM(AL17:AO17) -> -329.53076 | N17: ='GEV Quarterly'!B90 -> -52.5 | O17: ='GEV Quarterly'!C90 -> -90.5 | P17: ='GEV Quarterly'!D90 -> -99.5 | Q17: ='GEV Quarterly'!E90 -> -150.5 | R17: ='GEV Quarterly'!F90 -> -107 | S17: ='GEV Quarterly'!G90 -> -80 | T17: ='GEV Quarterly'!H90 -> -104.5 | U17: ='GEV Quarterly'!I90 -> -108.5 | ... W17: ='GEV Quarterly'!K90 -> -37 | X17: =-'Key Drivers'!H97*SUM(X11:X16) -> -59.964846 | Y17: =-'Key Drivers'!H97*SUM(Y11:Y16) -> -68.647208 | Z17: =-'Key Drivers'!I97*SUM(Z11:Z16) -> -56.861659 | AA17: =-'Key Drivers'!I97*SUM(AA11:AA16) -> -62.66408 | AB17: =-'Key Drivers'!I97*SUM(AB11:AB16) -> -64.456989 | AC17: =-'Key Drivers'!I97*SUM(AC11:AC16) -> -71.561864 | AD17: =-'Key Drivers'!J97*SUM(AD11:AD16) -> -62.678985 | AE17: =-'Key Drivers'!J97*SUM(AE11:AE16) -> -68.360475 | AF17: =-'Key Drivers'!J97*SUM(AF11:AF16) -> -70.19334 | AG17: =-'Key Drivers'!J97*SUM(AG11:AG16) -> -77.533539 | AH17: =-'Key Drivers'!K97*SUM(AH11:AH16) -> -68.937771 | AI17: =-'Key Drivers'!K97*SUM(AI11:AI16) -> -74.707971 | AJ17: =-'Key Drivers'!K97*SUM(AJ11:AJ16) -> -76.329401 | AK17: =-'Key Drivers'!K97*SUM(AK11:AK16) -> -83.950544 | AL17: =-'Key Drivers'!L97*SUM(AL11:AL16) -> -75.482798 | AM17: =-'Key Drivers'!L97*SUM(AM11:AM16) -> -81.138869 | AN17: =-'Key Drivers'!L97*SUM(AN11:AN16) -> -82.649595 | AO17: =-'Key Drivers'!L97*SUM(AO11:AO16) -> -90.259503
C18: Total revenues | F18: =SUM(F11:F17) -> 34935 | G18: =SUM(G11:G17) -> 38069 | H18: =SUM(H11:H17) -> 46033.799 | I18: =SUM(I11:I17) -> 50853.374 | J18: =SUM(J11:J17) -> 55474.501 | K18: =SUM(K11:K17) -> 60481.212 | L18: =SUM(L11:L17) -> 65576.622 | N18: =SUM(N11:N17) -> 7260 | O18: =SUM(O11:O17) -> 8204 | P18: =SUM(P11:P17) -> 8913 | Q18: =SUM(Q11:Q17) -> 10558 | R18: =SUM(R11:R17) -> 8032 | S18: =SUM(S11:S17) -> 9112 | T18: =SUM(T11:T17) -> 9969 | U18: =SUM(U11:U17) -> 10956 | ... AO18: =SUM(AO11:AO17) -> 17961.641
C19: Growth, YoY | G19: =G18/F18-1 -> 0.08970946 | H19: =H18/G18-1 -> 0.20922007 | I19: =I18/H18-1 -> 0.10469645 | J19: =J18/I18-1 -> 0.090871602 | K19: =K18/J18-1 -> 0.09025246 | L19: =L18/K18-1 -> 0.084247826 | R19: =R18/N18-1 -> 0.10633609 | S19: =S18/O18-1 -> 0.11067772 | T19: =T18/P18-1 -> 0.11847863 | U19: =U18/Q18-1 -> 0.037696533 | V19: =V18/R18-1 -> 0.1624751 | W19: =W18/S18-1 -> 0.21850307 | X19: =X18/T18-1 -> 0.19701117 | Y19: =Y18/U18-1 -> 0.2468779 | ... AO19: =AO18/AK18-1 -> 0.07515091
C20: Check vs reported revenue (rounding) | E20: Actual quarters only | F20: =SUM(N20:Q20) -> 0 | G20: =SUM(R20:U20) -> 1 | H20: =SUM(V20:Y20) -> -3 | N20: =N18-'GEV Quarterly'!B12 -> 0 | O20: =O18-'GEV Quarterly'!C12 -> 0 | P20: =P18-'GEV Quarterly'!D12 -> 0 | Q20: =Q18-'GEV Quarterly'!E12 -> 0 | R20: =R18-'GEV Quarterly'!F12 -> 0 | S20: =S18-'GEV Quarterly'!G12 -> 1 | T20: =T18-'GEV Quarterly'!H12 -> 0 | U20: =U18-'GEV Quarterly'!I12 -> 0 | ... W20: =W18-'GEV Quarterly'!K12 -> -1
C22: Power | F22: =F11+F12 -> 18233 | G22: =G11+G12 -> 19873 | H22: =H11+H12 -> 23379.79 | I22: =I11+I12 -> 27339.129 | J22: =J11+J12 -> 30072.737 | K22: =K11+K12 -> 32947.385 | L22: =L11+L12 -> 35875.49 | N22: =N11+N12 -> 4061.5 | O22: =O11+O12 -> 4481.5 | P22: =P11+P12 -> 4232.5 | Q22: =Q11+Q12 -> 5457.5 | R22: =R11+R12 -> 4449 | S22: =S11+S12 -> 4785 | T22: =T11+T12 -> 4864.5 | U22: =U11+U12 -> 5774.5 | ... AO22: =AO11+AO12 -> 9894.7487
C23: Electrification | F23: =F13+F14 -> 7394 | G23: =G13+G14 -> 9486 | H23: =H13+H14 -> 14812.842 | I23: =I13+I14 -> 16875.495 | J23: =J13+J14 -> 19238.412 | K23: =K13+K14 -> 21510.621 | L23: =L13+L14 -> 23587.516 | N23: =N13+N14 -> 1612 | O23: =O13+O14 -> 1751 | P23: =P13+P14 -> 1889 | Q23: =Q13+Q14 -> 2142 | R23: =R13+R14 -> 1840 | S23: =S13+S14 -> 2162 | T23: =T13+T14 -> 2562 | U23: =U13+U14 -> 2922 | ... AO23: =AO13+AO14 -> 6362.1849
C24: Wind | F24: =F15+F16 -> 9701 | G24: =G15+G16 -> 9110 | H24: =H15+H16 -> 8031.7783 | I24: =I15+I16 -> 6894.2946 | J24: =J15+J16 -> 6442.119 | K24: =K15+K16 -> 6327.1312 | L24: =L15+L16 -> 6443.1475 | N24: =N15+N16 -> 1639 | O24: =O15+O16 -> 2062 | P24: =P15+P16 -> 2891 | Q24: =Q15+Q16 -> 3109 | R24: =R15+R16 -> 1850 | S24: =S15+S16 -> 2245 | T24: =T15+T16 -> 2647 | U24: =U15+U16 -> 2368 | ... AO24: =AO15+AO16 -> 1794.9671
C25: Power growth, YoY | G25: =G22/F22-1 -> 0.0899468 | H25: =H22/G22-1 -> 0.17646004 | I25: =I22/H22-1 -> 0.16934875 | J25: =J22/I22-1 -> 0.099988864 | K25: =K22/J22-1 -> 0.09558985 | L25: =L22/K22-1 -> 0.088872135 | R25: =R22/N22-1 -> 0.0954081 | S25: =S22/O22-1 -> 0.067722861 | T25: =T22/P22-1 -> 0.14932073 | U25: =U22/Q22-1 -> 0.058085204 | V25: =V22/R22-1 -> 0.11732974 | W25: =W22/S22-1 -> 0.1446186 | X25: =X22/T22-1 -> 0.19240847 | Y25: =Y22/U22-1 -> 0.23496743 | ... AO25: =AO22/AK22-1 -> 0.079565421
C26: Electrification growth, YoY | G26: =G23/F23-1 -> 0.28293211 | H26: =H23/G23-1 -> 0.56154777 | I26: =I23/H23-1 -> 0.13924763 | J26: =J23/I23-1 -> 0.14002057 | K26: =K23/J23-1 -> 0.11810793 | L26: =L23/K23-1 -> 0.096552066 | R26: =R23/N23-1 -> 0.14143921 | S26: =S23/O23-1 -> 0.23472302 | T26: =T23/P23-1 -> 0.35627316 | U26: =U23/Q23-1 -> 0.36414566 | V26: =V23/R23-1 -> 0.60815217 | W26: =W23/S23-1 -> 0.68223867 | X26: =X23/T23-1 -> 0.52257834 | Y26: =Y23/U23-1 -> 0.47706927 | ... AO26: =AO23/AK23-1 -> 0.085351044
C27: Wind growth, YoY | G27: =G24/F24-1 -> -0.060921554 | H27: =H24/G24-1 -> -0.11835584 | I27: =I24/H24-1 -> -0.14162289 | J27: =J24/I24-1 -> -0.06558693 | K27: =K24/J24-1 -> -0.017849366 | L27: =L24/K24-1 -> 0.018336318 | R27: =R24/N24-1 -> 0.12873703 | S27: =S24/O24-1 -> 0.088748788 | T27: =T24/P24-1 -> -0.084399862 | U27: =U24/Q24-1 -> -0.2383403 | V27: =V24/R24-1 -> -0.22594595 | W27: =W24/S24-1 -> -0.097550111 | X27: =X24/T24-1 -> -0.13424535 | Y27: =Y24/U24-1 -> -0.03626448 | ... AO27: =AO24/AK24-1 -> 0.018277768
C28: Equipment as % of revenue | F28: =(F11+F13+F15)/F18 -> 0.55213969 | G28: =(G11+G13+G15)/G18 -> 0.55990438 | H28: =(H11+H13+H15)/H18 -> 0.59999395 | I28: =(I11+I13+I15)/I18 -> 0.62135878 | J28: =(J11+J13+J15)/J18 -> 0.63795779 | K28: =(K11+K13+K15)/K18 -> 0.65490247 | L28: =(L11+L13+L15)/L18 -> 0.66920788 | N28: =(N11+N13+N15)/N18 -> 0.50454545 | O28: =(O11+O13+O15)/O18 -> 0.51669917 | P28: =(P11+P13+P15)/P18 -> 0.60260294 | Q28: =(Q11+Q13+Q15)/Q18 -> 0.56980489 | R28: =(R11+R13+R15)/R18 -> 0.53461155 | S28: =(S11+S13+S15)/S18 -> 0.54587357 | T28: =(T11+T13+T15)/T18 -> 0.60006019 | U28: =(U11+U13+U15)/U18 -> 0.55357795 | ... AO28: =(AO11+AO13+AO15)/AO18 -> 0.64733548
C29: Data-centre-exposed equipment, % of revenue | F29: =(F11+F13)/F18 -> 0.32179762 | G29: =(G11+G13)/G18 -> 0.36943445 | H29: =(H11+H13)/H18 -> 0.47744208 | I29: =(I11+I13)/I18 -> 0.53466965 | J29: =(J11+J13)/J18 -> 0.56798541 | K29: =(K11+K13)/K18 -> 0.59389373 | L29: =(L11+L13)/L18 -> 0.61237694 | N29: =(N11+N13)/N18 -> 0.33484848 | O29: =(O11+O13)/O18 -> 0.31338372 | P29: =(P11+P13)/P18 -> 0.32278694 | Q29: =(Q11+Q13)/Q18 -> 0.31852624 | R29: =(R11+R13)/R18 -> 0.35881474 | S29: =(S11+S13)/S18 -> 0.34866111 | T29: =(T11+T13)/T18 -> 0.37907513 | U29: =(U11+U13)/U18 -> 0.38572472 | ... AO29: =(AO11+AO13)/AO18 -> 0.58923952
C31: 1. Data-centre demand
C32: Microsoft | D32: $B | E32: Calendar-year capex; FY26E per Jul-26 guide | F32: 74.5 | G32: 108.3 | H32: 175
C33: Amazon | D33: $B | E33: Annual driver; orders phased by quarter | F33: 83.9 | G33: 134.8 | H33: 220
C34: Alphabet | D34: $B | F34: 52.9 | G34: 93 | H34: 200
C35: Meta | D35: $B | F35: 38.4 | G35: 72.6 | H35: 137.5
C36: Hyperscaler capex, big four | D36: $B | E36: FY27E+ = prior year x (1 + scenario growth) | F36: =SUM(F32:F35) -> 249.7 | G36: =SUM(G32:G35) -> 408.7 | H36: =SUM(H32:H35) -> 732.5 | I36: =H36*(1+'Key Drivers'!I11) -> 915.625 | J36: =I36*(1+'Key Drivers'!J11) -> 1007.1875 | K36: =J36*(1+'Key Drivers'!K11) -> 1057.5469 | L36: =K36*(1+'Key Drivers'!L11) -> 1089.2733
C37: Growth, YoY | G37: =G36/F36-1 -> 0.63676412 | H37: =H36/G36-1 -> 0.79226817 | I37: =I36/H36-1 -> 0.25 | J37: =J36/I36-1 -> 0.1 | K37: =K36/J36-1 -> 0.05 | L37: =L36/K36-1 -> 0.03
C39: Gas Power equipment revenue as % of hyperscaler capex | F39: =F69/(F36*1000) -> 0.022859431 | G39: =G69/(G36*1000) -> 0.016359188 | H39: =H69/(H36*1000) -> 0.012760997 | I39: =I69/(I36*1000) -> 0.013766717 | J39: =J69/(J36*1000) -> 0.014571001 | K39: =K69/(K36*1000) -> 0.016013 | L39: =L69/(L36*1000) -> 0.017646708
C40: Electrification equipment, % of hyperscaler capex | F40: =F91/(F36*1000) -> 0.022162595 | G40: =G91/(G36*1000) -> 0.018052361 | H40: =H91/(H36*1000) -> 0.017243744 | I40: =I91/(I36*1000) -> 0.015928579 | J40: =J91/(J36*1000) -> 0.016712854 | K40: =K91/(K36*1000) -> 0.017951842 | L40: =L91/(L36*1000) -> 0.019219717
C41: Data-centre-exposed equipment, % of capex | E41: Falls when capex outgrows what GEV can build | F41: =(F69+F91)/(F36*1000) -> 0.045022026 | G41: =(G69+G91)/(G36*1000) -> 0.034411549 | H41: =(H69+H91)/(H36*1000) -> 0.030004741 | I41: =(I69+I91)/(I36*1000) -> 0.029695296 | J41: =(J69+J91)/(J36*1000) -> 0.031283855 | K41: =(K69+K91)/(K36*1000) -> 0.033964842 | L41: =(L69+L91)/(L36*1000) -> 0.036866424
C43: 2. Power: gas turbines
C44: Slot reservation agreements (SRAs), not in RPO
C45: Opening SRAs | D45: GW | H45: =V45 -> 43 | I45: =Z45 -> 65.7072 | J45: =AD45 -> 68.328091 | K45: =AH45 -> 65.746196 | L45: =AL45 -> 61.501498 | V45: =U49 -> 43 | W45: =V49 -> 56 | X45: =W49 -> 63 | Y45: =X49 -> 64.44 | Z45: =Y49 -> 65.7072 | AA45: =Z49 -> 66.472212 | AB45: =AA49 -> 67.15881 | AC45: =AB49 -> 67.775032 | ... AO45: =AN49 -> 57.977038
C46: (+) New reservations signed | D46: GW | E46: Q1-Q2'26 derived from closing balance | H46: =SUM(V46:Y46) -> 54.2 | I46: =SUM(Z46:AC46) -> 30 | J46: =SUM(AD46:AG46) -> 25 | K46: =SUM(AH46:AK46) -> 22 | L46: =SUM(AL46:AO46) -> 20 | V46: =V49-V45+V47 -> 19.1 | W46: =W49-W45+W47 -> 17.1 | X46: ='Key Drivers'!H32 -> 9 | Y46: ='Key Drivers'!H32 -> 9 | Z46: ='Key Drivers'!I32 -> 7.5 | AA46: ='Key Drivers'!I32 -> 7.5 | AB46: ='Key Drivers'!I32 -> 7.5 | AC46: ='Key Drivers'!I32 -> 7.5 | AD46: ='Key Drivers'!J32 -> 6.25 | AE46: ='Key Drivers'!J32 -> 6.25 | AF46: ='Key Drivers'!J32 -> 6.25 | AG46: ='Key Drivers'!J32 -> 6.25 | AH46: ='Key Drivers'!K32 -> 5.5 | AI46: ='Key Drivers'!K32 -> 5.5 | AJ46: ='Key Drivers'!K32 -> 5.5 | AK46: ='Key Drivers'!K32 -> 5.5 | AL46: ='Key Drivers'!L32 -> 5 | AM46: ='Key Drivers'!L32 -> 5 | AN46: ='Key Drivers'!L32 -> 5 | AO46: ='Key Drivers'!L32 -> 5
...

Sheet Key Drivers
C2: GE Vernova (GEV)
C3: Key drivers and scenario switch
C4: US$ millions unless stated. Blue = input, black = formula, orange = assumption, grey = projection. Annual columns add up the quarters.
C5: Scenario | D5: Base | E5: =IF(D5="Base","Base: build-out continues at a Street-like pace. FY28E revenue lands near the thesis base case ($55B).",IF(D5="Bull","Bull: faster build-out, SRAs convert, pricing holds. FY28E revenue lands near the thesis bull case ($58B).","Bear: build-out stalls after 2026. Capex flat then down, SRAs lapse, deliveries slip. FY28E revenue lands near the thesis bear case ($50B).")) -> Base: build-out continues at a Street-like pace. FY28E revenue lands near the thesis base case ($55B).
C6: <- change the scenario in the orange cell (Base / Bull / Bear) | F6: Annual: historical | H6: Annual: projected | N6: Quarterly: historical | X6: Quarterly: projected
C7: Fiscal period | D7: Unit | E7: Note | F7: FY2024A | G7: FY2025A | H7: FY2026E | I7: FY2027E | J7: FY2028E | K7: FY2029E | L7: FY2030E | N7: Q1'24 | O7: Q2'24 | P7: Q3'24 | Q7: Q4'24 | R7: Q1'25 | S7: Q2'25 | T7: Q3'25 | U7: Q4'25 | V7: Q1'26 | W7: Q2'26 | X7: Q3'26 | Y7: Q4'26 | Z7: Q1'27 | AA7: Q2'27 | AB7: Q3'27 | AC7: Q4'27 | AD7: Q1'28 | AE7: Q2'28 | AF7: Q3'28 | AG7: Q4'28 | AH7: Q1'29 | AI7: Q2'29 | AJ7: Q3'29 | AK7: Q4'29 | AL7: Q1'30 | AM7: Q2'30 | AN7: Q3'30 | AO7: Q4'30
C8: Period end | F8: 45657 | G8: 46022 | H8: 46387 | I8: 46752 | J8: 47118 | K8: 47483 | L8: 47848 | N8: 45382 | O8: 45473 | P8: 45565 | Q8: 45657 | R8: 45747 | S8: 45838 | T8: 45930 | U8: 46022 | V8: 46112 | W8: 46203 | X8: 46295 | Y8: 46387 | Z8: 46477 | AA8: 46568 | AB8: 46660 | AC8: 46752 | AD8: 46843 | AE8: 46934 | AF8: 47026 | AG8: 47118 | AH8: 47208 | AI8: 47299 | AJ8: 47391 | AK8: 47483 | AL8: 47573 | AM8: 47664 | AN8: 47756 | AO8: 47848
C10: 1. Data-centre demand
C11: Hyperscaler capex growth, YoY | E11: FY26E = guide $732.5B; Street ~$1T FY27 | G11: =Revenue!G37 -> 0.63676412 | H11: =Revenue!H37 -> 0.79226817 | I11: =INDEX(I12:I14,MATCH($D$5,$C12:$C14,0)) -> 0.25 | J11: =INDEX(J12:J14,MATCH($D$5,$C12:$C14,0)) -> 0.1 | K11: =INDEX(K12:K14,MATCH($D$5,$C12:$C14,0)) -> 0.05 | L11: =INDEX(L12:L14,MATCH($D$5,$C12:$C14,0)) -> 0.03
C12: Base | I12: 0.25 | J12: 0.1 | K12: 0.05 | L12: 0.03
C13: Bull | I13: 0.37 | J13: 0.12 | K13: 0.08 | L13: 0.05
C14: Bear | I14: 0 | J14: -0.1 | K14: -0.05 | L14: 0
C16: Data-centre orders, % of hyperscaler capex | E16: H1'26 >$5B on ~$733B capex; annual rate | G16: =Revenue!G79 -> 0.005872278 | H16: =INDEX(H17:H19,MATCH($D$5,$C17:$C19,0)) -> 0.0143 | I16: =INDEX(I17:I19,MATCH($D$5,$C17:$C19,0)) -> 0.0145 | J16: =INDEX(J17:J19,MATCH($D$5,$C17:$C19,0)) -> 0.0145 | K16: =INDEX(K17:K19,MATCH($D$5,$C17:$C19,0)) -> 0.014 | L16: =INDEX(L17:L19,MATCH($D$5,$C17:$C19,0)) -> 0.014
C17: Base | H17: 0.0143 | I17: 0.0145 | J17: 0.0145 | K17: 0.014 | L17: 0.014
C18: Bull | H18: 0.0147 | I18: 0.015 | J18: 0.0152 | K18: 0.0152 | L18: 0.0152
C19: Bear | H19: 0.014 | I19: 0.0125 | J19: 0.0115 | K19: 0.011 | L19: 0.011
C21: Other Electrification equipment orders, YoY | E21: Grid, power conversion, other | H21: =INDEX(H22:H24,MATCH($D$5,$C22:$C24,0)) -> -0.08 | I21: =INDEX(I22:I24,MATCH($D$5,$C22:$C24,0)) -> 0.05 | J21: =INDEX(J22:J24,MATCH($D$5,$C22:$C24,0)) -> 0.05 | K21: =INDEX(K22:K24,MATCH($D$5,$C22:$C24,0)) -> 0.04 | L21: =INDEX(L22:L24,MATCH($D$5,$C22:$C24,0)) -> 0.03
C22: Base | H22: -0.08 | I22: 0.05 | J22: 0.05 | K22: 0.04 | L22: 0.03
C23: Bull | H23: -0.06 | I23: 0.06 | J23: 0.06 | K23: 0.05 | L23: 0.04
C24: Bear | H24: -0.09 | I24: 0.01 | J24: -0.02 | K24: -0.01 | L24: 0
C26: Electrification backlog delivered, % per quarter | E26: Per quarter, on opening backlog | G26: =(SUM(Revenue!R91:U91)-$H$96*SUM(Revenue!R90:U90))/(SUM(Revenue!R88:U88)+SUM(Revenue!R89:U89)) -> 0.070168063 | H26: =INDEX(H27:H29,MATCH($D$5,$C27:$C29,0)) -> 0.075 | I26: =INDEX(I27:I29,MATCH($D$5,$C27:$C29,0)) -> 0.064 | J26: =INDEX(J27:J29,MATCH($D$5,$C27:$C29,0)) -> 0.059 | K26: =INDEX(K27:K29,MATCH($D$5,$C27:$C29,0)) -> 0.056 | L26: =INDEX(L27:L29,MATCH($D$5,$C27:$C29,0)) -> 0.054
C27: Base | H27: 0.075 | I27: 0.064 | J27: 0.059 | K27: 0.056 | L27: 0.054
C28: Bull | H28: 0.077 | I28: 0.066 | J28: 0.06 | K28: 0.057 | L28: 0.055
C29: Bear | H29: 0.073 | I29: 0.06 | J29: 0.054 | K29: 0.051 | L29: 0.049
C31: 2. Gas Power
C32: New slot reservation agreements signed, per quarter | D32: GW | E32: Per quarter; Q2'26 was 18 GW | H32: =INDEX(H33:H35,MATCH($D$5,$C33:$C35,0)) -> 9 | I32: =INDEX(I33:I35,MATCH($D$5,$C33:$C35,0)) -> 7.5 | J32: =INDEX(J33:J35,MATCH($D$5,$C33:$C35,0)) -> 6.25 | K32: =INDEX(K33:K35,MATCH($D$5,$C33:$C35,0)) -> 5.5 | L32: =INDEX(L33:L35,MATCH($D$5,$C33:$C35,0)) -> 5
C33: Base | H33: 9 | I33: 7.5 | J33: 6.25 | K33: 5.5 | L33: 5
C34: Bull | H34: 10.9 | I34: 9 | J34: 8 | K34: 7 | L34: 6.5
C35: Bear | H35: 5.9 | I35: 3 | J35: 1.5 | K35: 1 | L35: 1
C37: SRAs converting to firm orders, % per quarter | E37: Per quarter; Q2'26 was 17.9% (10 of 56 GW) | H37: =INDEX(H38:H40,MATCH($D$5,$C38:$C40,0)) -> 0.12 | I37: =INDEX(I38:I40,MATCH($D$5,$C38:$C40,0)) -> 0.095 | J37: =INDEX(J38:J40,MATCH($D$5,$C38:$C40,0)) -> 0.095 | K37: =INDEX(K38:K40,MATCH($D$5,$C38:$C40,0)) -> 0.095 | L37: =INDEX(L38:L40,MATCH($D$5,$C38:$C40,0)) -> 0.095
C38: Base | H38: 0.12 | I38: 0.095 | J38: 0.095 | K38: 0.095 | L38: 0.095
C39: Bull | H39: 0.125 | I39: 0.105 | J39: 0.105 | K39: 0.105 | L39: 0.105
C40: Bear | H40: 0.11 | I40: 0.0625 | J40: 0.0625 | K40: 0.0625 | L40: 0.0625
C42: SRAs lapsing or cancelled, % per quarter | E42: Per quarter | H42: =INDEX(H43:H45,MATCH($D$5,$C43:$C45,0)) -> 0 | I42: =INDEX(I43:I45,MATCH($D$5,$C43:$C45,0)) -> 0.0075 | J42: =INDEX(J43:J45,MATCH($D$5,$C43:$C45,0)) -> 0.0075 | K42: =INDEX(K43:K45,MATCH($D$5,$C43:$C45,0)) -> 0.0075 | L42: =INDEX(L43:L45,MATCH($D$5,$C43:$C45,0)) -> 0.0075
C43: Base | H43: 0 | I43: 0.0075 | J43: 0.0075 | K43: 0.0075 | L43: 0.0075
C44: Bull | H44: 0 | I44: 0.0025 | J44: 0.0025 | K44: 0.0025 | L44: 0.0025
C45: Bear | H45: 0 | I45: 0.03 | J45: 0.03 | K45: 0.03 | L45: 0.03
C47: Direct firm orders (no prior SRA), per quarter | D47: GW | E47: Per quarter; Q2'26 was 2 GW | H47: =INDEX(H48:H50,MATCH($D$5,$C48:$C50,0)) -> 2 | I47: =INDEX(I48:I50,MATCH($D$5,$C48:$C50,0)) -> 1.5 | J47: =INDEX(J48:J50,MATCH($D$5,$C48:$C50,0)) -> 1.5 | K47: =INDEX(K48:K50,MATCH($D$5,$C48:$C50,0)) -> 1.5 | L47: =INDEX(L48:L50,MATCH($D$5,$C48:$C50,0)) -> 1.5
C48: Base | H48: 2 | I48: 1.5 | J48: 1.5 | K48: 1.5 | L48: 1.5
C49: Bull | H49: 2 | I49: 2 | J49: 2 | K49: 2 | L49: 2
...

Sheet Regular DCF
C2: GE Vernova (GEV)
C3: Regular DCF: quarterly, 6-month view
C4: US$ millions unless stated. Blue = input, black = formula, orange = assumption, grey = projection.
C5: Scenario | E5: ='Key Drivers'!D5 -> Base
F6: Actual | H6: Projected quarters | S6: Fiscal year
C7: Fiscal period | E7: Note | F7: Q1'26A | G7: Q2'26A | H7: Q3'26E | I7: Q4'26E | J7: Q1'27E | K7: Q2'27E | L7: Q3'27E | M7: Q4'27E | N7: Q1'28E | O7: Q2'28E | P7: Q3'28E | Q7: Q4'28E | S7: FY2026E | T7: FY2027E | U7: FY2028E | V7: FY2029E
C8: Period end | F8: 46112 | G8: 46203 | H8: 46295 | I8: 46387 | J8: 46477 | K8: 46568 | L8: 46660 | M8: 46752 | N8: 46843 | O8: 46934 | P8: 47026 | Q8: 47118 | S8: 46387 | T8: 46752 | U8: 47118 | V8: 47483
C10: Cash flow
C11: Revenue | E11: Revenue tab | F11: =Revenue!V18 -> 9337 | G11: =Revenue!W18 -> 11103 | H11: =Revenue!X18 -> 11933.004 | I11: =Revenue!Y18 -> 13660.794 | J11: =Revenue!Z18 -> 11315.47 | K11: =Revenue!AA18 -> 12470.152 | L11: =Revenue!AB18 -> 12826.941 | M11: =Revenue!AC18 -> 14240.811 | ... Q11: =Revenue!AG18 -> 15429.174 | S11: =SUM(F11:I11) -> 46033.799 | T11: =SUM(J11:M11) -> 50853.374 | U11: =SUM(N11:Q11) -> 55474.501 | V11: =Revenue!K18 -> 60481.212
C12: Growth, YoY | F12: =F11/Revenue!R18-1 -> 0.1624751 | G12: =G11/Revenue!S18-1 -> 0.21850307 | H12: =H11/Revenue!T18-1 -> 0.19701117 | I12: =I11/Revenue!U18-1 -> 0.2468779 | J12: =J11/Revenue!V18-1 -> 0.2118957 | K12: =K11/Revenue!W18-1 -> 0.12313357 | L12: =L11/Revenue!X18-1 -> 0.074912937 | M12: =M11/Revenue!Y18-1 -> 0.04245848 | ... Q12: =Q11/Revenue!AC18-1 -> 0.083447733 | S12: =S11/Revenue!$G$18-1 -> 0.20922007 | T12: =T11/S11-1 -> 0.10469645 | U12: =U11/T11-1 -> 0.090871602 | V12: =V11/U11-1 -> 0.09025246
C13: Adjusted EBITDA | E13: Revenue x margin (Key Drivers) | F13: ='GEV Quarterly'!J57 -> 896 | G13: ='GEV Quarterly'!K57 -> 1250 | H13: =H11*($S11*'Key Drivers'!$H$104-SUM($F13:$G13))/SUM($H11:$I11) -> 1789.6355 | I13: =I11*($S11*'Key Drivers'!$H$104-SUM($F13:$G13))/SUM($H11:$I11) -> 2048.7583 | J13: =J11*'Key Drivers'!$I$104 -> 1652.0586 | K13: =K11*'Key Drivers'!$I$104 -> 1820.6422 | L13: =L11*'Key Drivers'!$I$104 -> 1872.7334 | M13: =M11*'Key Drivers'!$I$104 -> 2079.1584 | N13: =N11*'Key Drivers'!$J$104 -> 1995.6989 | O13: =O11*'Key Drivers'!$J$104 -> 2176.5975 | P13: =P11*'Key Drivers'!$J$104 -> 2234.956 | Q13: =Q11*'Key Drivers'!$J$104 -> 2468.6679 | S13: =SUM(F13:I13) -> 5984.3938 | T13: =SUM(J13:M13) -> 7424.5926 | U13: =SUM(N13:Q13) -> 8875.9202 | V13: =V11*'Key Drivers'!$K$104 -> 9676.9939
C14: Margin | E14: H2'26 = FY26E less H1 actual | F14: =F13/F11 -> 0.095962301 | G14: =G13/G11 -> 0.11258218 | H14: =H13/H11 -> 0.14997359 | I14: =I13/I11 -> 0.14997359 | J14: =J13/J11 -> 0.146 | K14: =K13/K11 -> 0.146 | L14: =L13/L11 -> 0.146 | M14: =M13/M11 -> 0.146 | ... Q14: =Q13/Q11 -> 0.16 | S14: =S13/S11 -> 0.13 | T14: =T13/T11 -> 0.146 | U14: =U13/U11 -> 0.16 | V14: =V13/V11 -> 0.16
C15: D&A | F15: ='GEV Quarterly'!J54 -> 341 | G15: ='GEV Quarterly'!K54 -> 418 | H15: =H11*'Key Drivers'!$H$120 -> 417.65515 | I15: =I11*'Key Drivers'!$H$120 -> 478.1278 | J15: =J11*'Key Drivers'!$I$120 -> 373.41051 | K15: =K11*'Key Drivers'!$I$120 -> 411.51502 | L15: =L11*'Key Drivers'!$I$120 -> 423.28905 | M15: =M11*'Key Drivers'!$I$120 -> 469.94676 | N15: =N11*'Key Drivers'!$J$120 -> 386.66666 | O15: =O11*'Key Drivers'!$J$120 -> 421.71577 | P15: =P11*'Key Drivers'!$J$120 -> 433.02272 | Q15: =Q11*'Key Drivers'!$J$120 -> 478.3044 | S15: =SUM(F15:I15) -> 1654.783 | T15: =SUM(J15:M15) -> 1678.1613 | U15: =SUM(N15:Q15) -> 1719.7095
C16: Adjusted EBIT | F16: =F13-F15 -> 555 | G16: =G13-G15 -> 832 | H16: =H13-H15 -> 1371.9803 | I16: =I13-I15 -> 1570.6305 | J16: =J13-J15 -> 1278.6481 | K16: =K13-K15 -> 1409.1272 | L16: =L13-L15 -> 1449.4443 | M16: =M13-M15 -> 1609.2116 | ... Q16: =Q13-Q15 -> 1990.3635 | S16: =S13-S15 -> 4329.6109 | T16: =T13-T15 -> 5746.4312 | U16: =U13-U15 -> 7156.2107
C17: Taxes | F17: =F16*'Key Drivers'!$H$124 -> 138.75 | G17: =G16*'Key Drivers'!$H$124 -> 208 | H17: =H16*'Key Drivers'!$H$124 -> 342.99508 | I17: =I16*'Key Drivers'!$H$124 -> 392.65764 | J17: =J16*'Key Drivers'!$I$124 -> 319.66203 | K17: =K16*'Key Drivers'!$I$124 -> 352.28179 | L17: =L16*'Key Drivers'!$I$124 -> 362.36108 | M17: =M16*'Key Drivers'!$I$124 -> 402.30291 | N17: =N16*'Key Drivers'!$J$124 -> 402.25805 | O17: =O16*'Key Drivers'!$J$124 -> 438.72044 | P17: =P16*'Key Drivers'!$J$124 -> 450.48331 | Q17: =Q16*'Key Drivers'!$J$124 -> 497.59087 | S17: =SUM(F17:I17) -> 1082.4027 | T17: =SUM(J17:M17) -> 1436.6078 | U17: =SUM(N17:Q17) -> 1789.0527
C18: NOPAT | F18: =F16-F17 -> 416.25 | G18: =G16-G17 -> 624 | H18: =H16-H17 -> 1028.9853 | I18: =I16-I17 -> 1177.9729 | J18: =J16-J17 -> 958.98609 | K18: =K16-K17 -> 1056.8454 | L18: =L16-L17 -> 1087.0832 | M18: =M16-M17 -> 1206.9087 | ... Q18: =Q16-Q17 -> 1492.7726 | S18: =S16-S17 -> 3247.2082 | T18: =T16-T17 -> 4309.8234 | U18: =U16-U17 -> 5367.158
C19: Add back: D&A | F19: =F15 -> 341 | G19: =G15 -> 418 | H19: =H15 -> 417.65515 | I19: =I15 -> 478.1278 | J19: =J15 -> 373.41051 | K19: =K15 -> 411.51502 | L19: =L15 -> 423.28905 | M19: =M15 -> 469.94676 | ... Q19: =Q15 -> 478.3044 | S19: =S15 -> 1654.783 | T19: =T15 -> 1678.1613 | U19: =U15 -> 1719.7095
C20: Capex | F20: ='GEV Quarterly'!J308 -> -397 | G20: ='GEV Quarterly'!K308 -> -386 | H20: =-H11*'Key Drivers'!$H$121 -> -381.85614 | I20: =-I11*'Key Drivers'!$H$121 -> -437.14542 | J20: =-J11*'Key Drivers'!$I$121 -> -362.09504 | K20: =-K11*'Key Drivers'!$I$121 -> -399.04486 | L20: =-L11*'Key Drivers'!$I$121 -> -410.46211 | M20: =-M11*'Key Drivers'!$I$121 -> -455.70595 | N20: =-N11*'Key Drivers'!$J$121 -> -374.19354 | O20: =-O11*'Key Drivers'!$J$121 -> -408.11203 | P20: =-P11*'Key Drivers'!$J$121 -> -419.05424 | Q20: =-Q11*'Key Drivers'!$J$121 -> -462.87523 | S20: =SUM(F20:I20) -> -1602.0016 | T20: =SUM(J20:M20) -> -1627.308 | U20: =SUM(N20:Q20) -> -1664.235
C21: Working capital | E21: % of revenue change | F21: =SUM('GEV Quarterly'!J301:J304) -> -264 | G21: =SUM('GEV Quarterly'!K301:K304) -> -1732 | H21: =-'Key Drivers'!$H$122*(H11-Revenue!T18) -> -1178.4026 | I21: =-'Key Drivers'!$H$122*(I11-Revenue!U18) -> -1622.8766 | J21: =-'Key Drivers'!$I$122*(J11-Revenue!V18) -> -989.23506 | K21: =-'Key Drivers'!$I$122*(K11-Revenue!W18) -> -683.57601 | L21: =-'Key Drivers'!$I$122*(L11-Revenue!X18) -> -446.9682 | M21: =-'Key Drivers'!$I$122*(M11-Revenue!Y18) -> -290.00828 | N21: =-'Key Drivers'!$J$122*(N11-Revenue!Z18) -> -463.05912 | O21: =-'Key Drivers'!$J$122*(O11-Revenue!AA18) -> -453.43298 | P21: =-'Key Drivers'!$J$122*(P11-Revenue!AB18) -> -456.61356 | Q21: =-'Key Drivers'!$J$122*(Q11-Revenue!AC18) -> -475.34536 | S21: =SUM(F21:I21) -> -4797.2792 | T21: =SUM(J21:M21) -> -2409.7876 | U21: =SUM(N21:Q21) -> -1848.451
C22: Customer deposits | E22: Change in balance below | F22: ='GEV Quarterly'!J305 -> 5574 | G22: ='GEV Quarterly'!K305 -> 8121 | H22: =H41-G41 -> 1924.3537 | I22: =I41-H41 -> 1495.7801 | J22: =J41-I41 -> 1417.4699 | K22: =K41-J41 -> 1223.4016 | L22: =L41-K41 -> 1400.6517 | M22: =M41-L41 -> 1700.4108 | N22: =N41-M41 -> 1100.8719 | O22: =O41-N41 -> 985.10238 | ... Q22: =Q41-P41 -> 1425.4347 | S22: =SUM(F22:I22) -> 17115.134 | T22: =SUM(J22:M22) -> 5741.9341 | U22: =SUM(N22:Q22) -> 4645.0897
C23: Pension and other | F23: =SUM('GEV Quarterly'!J297:J298)+'GEV Quarterly'!J306 -> -627 | G23: =SUM('GEV Quarterly'!K297:K298)+'GEV Quarterly'!K306 -> -1493 | H23: =-H11*'Key Drivers'!$H$123 -> -298.32511 | I23: =-I11*'Key Drivers'!$H$123 -> -341.51986 | J23: =-J11*'Key Drivers'!$I$123 -> -226.3094 | K23: =-K11*'Key Drivers'!$I$123 -> -249.40304 | L23: =-L11*'Key Drivers'!$I$123 -> -256.53882 | M23: =-M11*'Key Drivers'!$I$123 -> -284.81622 | N23: =-N11*'Key Drivers'!$J$123 -> -187.09677 | O23: =-O11*'Key Drivers'!$J$123 -> -204.05602 | P23: =-P11*'Key Drivers'!$J$123 -> -209.52712 | Q23: =-Q11*'Key Drivers'!$J$123 -> -231.43761 | S23: =SUM(F23:I23) -> -2759.845 | T23: =SUM(J23:M23) -> -1017.0675 | U23: =SUM(N23:Q23) -> -832.11752
C24: Unlevered free cash flow | F24: =F18+F19+F20+F21+F22+F23 -> 5043.25 | G24: =G18+G19+G20+G21+G22+G23 -> 5552 | H24: =H18+H19+H20+H21+H22+H23 -> 1512.4102 | I24: =I18+I19+I20+I21+I22+I23 -> 750.33892 | J24: =J18+J19+J20+J21+J22+J23 -> 1172.227 | K24: =K18+K19+K20+K21+K22+K23 -> 1359.7381 | L24: =L18+L19+L20+L21+L22+L23 -> 1797.0548 | M24: =M18+M19+M20+M21+M22+M23 -> 2346.7359 | ... Q24: =Q18+Q19+Q20+Q21+Q22+Q23 -> 2226.8535 | S24: =S18+S19+S20+S21+S22+S23 -> 12857.999 | T24: =T18+T19+T20+T21+T22+T23 -> 6675.7559 | U24: =U18+U19+U20+U21+U22+U23 -> 7387.1537
C25: Memo: UFCF excl. deposits | E25: What the business earns on its own | F25: =F24-F22 -> -530.75 | G25: =G24-G22 -> -2569 | H25: =H24-H22 -> -411.94348 | I25: =I24-I22 -> -745.44116 | J25: =J24-J22 -> -245.2429 | K25: =K24-K22 -> 136.33649 | L25: =L24-L22 -> 396.40315 | M25: =M24-M22 -> 646.32504 | ... Q25: =Q24-Q22 -> 801.41882 | S25: =S24-S22 -> -4257.1346 | T25: =T24-T22 -> 933.82178 | U25: =U24-U22 -> 2742.064
C27: Discount period (years) | E27: Mid-quarter, from 30-Jun-26 | H27: =(H$8-$N$49)/365-0.125 -> 0.12705479 | I27: =(I$8-$N$49)/365-0.125 -> 0.37910959 | J27: =(J$8-$N$49)/365-0.125 -> 0.62568493 | K27: =(K$8-$N$49)/365-0.125 -> 0.875 | L27: =(L$8-$N$49)/365-0.125 -> 1.1270548 | M27: =(M$8-$N$49)/365-0.125 -> 1.3791096 | N27: =(N$8-$N$49)/365-0.125 -> 1.6284247 | O27: =(O$8-$N$49)/365-0.125 -> 1.8777397 | ... Q27: =(Q$8-$N$49)/365-0.125 -> 2.3818493
C28: Discount factor | H28: =1/(1+$N$53)^H27 -> 0.98809383 | I28: =1/(1+$N$53)^I27 -> 0.96489197 | J28: =1/(1+$N$53)^J27 -> 0.94272176 | K28: =1/(1+$N$53)^K27 -> 0.9208231 | L28: =1/(1+$N$53)^L27 -> 0.89920085 | M28: =1/(1+$N$53)^M27 -> 0.87808632 | N28: =1/(1+$N$53)^N27 -> 0.85768908 | O28: =1/(1+$N$53)^O27 -> 0.83776566 | ... Q28: =1/(1+$N$53)^Q27 -> 0.7988837
C29: PV of UFCF | H29: =H24*H28 -> 1494.4032 | I29: =I24*I28 -> 723.996 | J29: =J24*J28 -> 1105.0839 | K29: =K24*K28 -> 1252.0783 | L29: =L24*L28 -> 1615.9132 | M29: =M24*M28 -> 2060.6367 | N29: =N24*N28 -> 1432.3093 | O29: =O24*O28 -> 1388.4947 | ... Q29: =Q24*Q28 -> 1778.997
C31: Customer deposits
C32: Firm gas backlog (GW) | E32: Revenue tab | F32: =Revenue!V58 -> 44 | G32: =Revenue!W58 -> 53 | H32: =Revenue!X58 -> 58.17375 | I32: =Revenue!Y58 -> 63.033833 | J32: =Revenue!Z58 -> 66.047225 | K32: =Revenue!AA58 -> 68.943526 | L32: =Revenue!AB58 -> 71.808433 | M32: =Revenue!AC58 -> 74.542301 | ... Q32: =Revenue!AG58 -> 83.634677
C33: Power equipment RPO | E33: GW x $741mm per GW | F33: ='GEV Quarterly'!J236 -> 28530 | G33: ='GEV Quarterly'!K236 -> 39261 | H33: =H32*'Key Drivers'!$H$125 -> 43106.749 | I33: =I32*'Key Drivers'!$H$125 -> 46708.07 | J33: =J32*'Key Drivers'!$I$125 -> 48940.993 | K33: =K32*'Key Drivers'!$I$125 -> 51087.152 | L33: =L32*'Key Drivers'!$I$125 -> 53210.049 | M33: =M32*'Key Drivers'!$I$125 -> 55235.845 | N33: =N32*'Key Drivers'!$J$125 -> 57202.452 | O33: =O32*'Key Drivers'!$J$125 -> 58977.205 | P33: =P32*'Key Drivers'!$J$125 -> 60565.782 | Q33: =Q32*'Key Drivers'!$J$125 -> 61973.296
C34: Electrification equipment RPO | E34: Revenue tab backlog | F34: ='GEV Quarterly'!J240 -> 38598 | G34: ='GEV Quarterly'!K240 -> 40589 | H34: =Revenue!X92 -> 43408.048 | I34: =Revenue!Y92 -> 47594.228 | J34: =Revenue!Z92 -> 49912.127 | K34: =Revenue!AA92 -> 52349.877 | L34: =Revenue!AB92 -> 55972.593 | M34: =Revenue!AC92 -> 61240.831 | N34: =Revenue!AD92 -> 63385.876 | O34: =Revenue!AE92 -> 65692.275 | ... Q34: =Revenue!AG92 -> 74714.451
C35: Wind equipment RPO | E35: 1.5x trailing Wind equipment revenue | F35: ='GEV Quarterly'!J244 -> 8905 | G35: ='GEV Quarterly'!K244 -> 8197 | H35: ='Key Drivers'!$H$128*SUM(Revenue!U105:X105) -> 8789.4788 | I35: ='Key Drivers'!$H$128*SUM(Revenue!V105:Y105) -> 8462.2924 | J35: ='Key Drivers'!$I$128*SUM(Revenue!W105:Z105) -> 8319.0697 | K35: ='Key Drivers'!$I$128*SUM(Revenue!X105:AA105) -> 7813.6062 | L35: ='Key Drivers'!$I$128*SUM(Revenue!Y105:AB105) -> 7192.4229 | M35: ='Key Drivers'!$I$128*SUM(Revenue!Z105:AC105) -> 6612.6519 | N35: ='Key Drivers'!$J$128*SUM(Revenue!AA105:AD105) -> 6470.429 | O35: ='Key Drivers'!$J$128*SUM(Revenue!AB105:AE105) -> 6280.7985 | P35: ='Key Drivers'!$J$128*SUM(Revenue!AC105:AF105) -> 6043.7604 | Q35: ='Key Drivers'!$J$128*SUM(Revenue!AD105:AG105) -> 5822.5248
C36: Total equipment RPO | F36: =F33+F34+F35 -> 76033 | G36: =G33+G34+G35 -> 88047 | H36: =H33+H34+H35 -> 95304.276 | I36: =I33+I34+I35 -> 102764.59 | J36: =J33+J34+J35 -> 107172.19 | K36: =K33+K34+K35 -> 111250.64 | L36: =L33+L34+L35 -> 116375.07 | M36: =M33+M34+M35 -> 123089.33 | ... Q36: =Q33+Q34+Q35 -> 142510.27
C37: Power deposits, % of Power RPO | E37: Key Drivers, by quarter | F37: ='GEV Quarterly'!J287/'GEV Quarterly'!J236 -> 0.64770417 | G37: ='GEV Quarterly'!K287/'GEV Quarterly'!K236 -> 0.6571152 | H37: =G37+('Key Drivers'!$H$109-G37)*0.5 -> 0.6235576 | I37: ='Key Drivers'!$H$109 -> 0.59 | J37: ='Key Drivers'!$H$109+('Key Drivers'!$I$109-'Key Drivers'!$H$109)*1/4 -> 0.5825 | K37: ='Key Drivers'!$H$109+('Key Drivers'!$I$109-'Key Drivers'!$H$109)*2/4 -> 0.575 | L37: ='Key Drivers'!$H$109+('Key Drivers'!$I$109-'Key Drivers'!$H$109)*3/4 -> 0.5675 | M37: ='Key Drivers'!$H$109+('Key Drivers'!$I$109-'Key Drivers'!$H$109)*4/4 -> 0.56 | N37: ='Key Drivers'!$I$109+('Key Drivers'!$J$109-'Key Drivers'!$I$109)*1/4 -> 0.5525 | O37: ='Key Drivers'!$I$109+('Key Drivers'!$J$109-'Key Drivers'!$I$109)*2/4 -> 0.545 | P37: ='Key Drivers'!$I$109+('Key Drivers'!$J$109-'Key Drivers'!$I$109)*3/4 -> 0.5375 | Q37: ='Key Drivers'!$I$109+('Key Drivers'!$J$109-'Key Drivers'!$I$109)*4/4 -> 0.53
C38: Power deposits | F38: ='GEV Quarterly'!J287 -> 18479 | G38: ='GEV Quarterly'!K287 -> 25799 | H38: =H33*H37 -> 26879.541 | I38: =I33*I37 -> 27557.761 | J38: =J33*J37 -> 28508.129 | K38: =K33*K37 -> 29375.113 | L38: =L33*L37 -> 30196.703 | M38: =M33*M37 -> 30932.073 | N38: =N33*N37 -> 31604.355 | O38: =O33*O37 -> 32142.577 | ... Q38: =Q33*Q37 -> 32845.847
C39: Electrification deposits | F39: ='GEV Quarterly'!J288 -> 8259 | G39: ='GEV Quarterly'!K288 -> 9113 | H39: =H34*'Key Drivers'!$H$126 -> 9766.8108 | I39: =I34*'Key Drivers'!$H$126 -> 10708.701 | J39: =J34*'Key Drivers'!$I$126 -> 11230.229 | K39: =K34*'Key Drivers'!$I$126 -> 11778.722 | L39: =L34*'Key Drivers'!$I$126 -> 12593.833 | M39: =M34*'Key Drivers'!$I$126 -> 13779.187 | N39: =N34*'Key Drivers'!$J$126 -> 14261.822 | O39: =O34*'Key Drivers'!$J$126 -> 14780.762 | P39: =P34*'Key Drivers'!$J$126 -> 15592.986 | Q39: =Q34*'Key Drivers'!$J$126 -> 16810.751
C40: Wind deposits | F40: ='GEV Quarterly'!J289 -> 3173 | G40: ='GEV Quarterly'!K289 -> 3150 | H40: =H35*'Key Drivers'!$H$127 -> 3340.002 | I40: =I35*'Key Drivers'!$H$127 -> 3215.6711 | J40: =J35*'Key Drivers'!$I$127 -> 3161.2465 | K40: =K35*'Key Drivers'!$I$127 -> 2969.1704 | L40: =L35*'Key Drivers'!$I$127 -> 2733.1207 | M40: =M35*'Key Drivers'!$I$127 -> 2512.8077 | N40: =N35*'Key Drivers'!$J$127 -> 2458.763 | O40: =O35*'Key Drivers'!$J$127 -> 2386.7034 | P40: =P35*'Key Drivers'!$J$127 -> 2296.6289 | Q40: =Q35*'Key Drivers'!$J$127 -> 2212.5594
C41: Total customer deposits | F41: =F38+F39+F40 -> 29911 | G41: =G38+G39+G40 -> 38062 | H41: =H38+H39+H40 -> 39986.354 | I41: =I38+I39+I40 -> 41482.134 | J41: =J38+J39+J40 -> 42899.604 | K41: =K38+K39+K40 -> 44123.005 | L41: =L38+L39+L40 -> 45523.657 | M41: =M38+M39+M40 -> 47224.068 | ... Q41: =Q38+Q39+Q40 -> 51869.158
C42: Deposits, % of equipment RPO | F42: =F41/F36 -> 0.39339497 | G42: =G41/G36 -> 0.43229184 | H42: =H41/H36 -> 0.41956516 | I42: =I41/I36 -> 0.40366174 | J42: =J41/J36 -> 0.40028671 | K42: =K41/K36 -> 0.39660902 | L42: =L41/L36 -> 0.39118051 | M42: =M41/M36 -> 0.38365688 | ... Q42: =Q41/Q36 -> 0.36396785
C44: Valuation | K44: Inputs
C45: Exit multiple (EV / FY2029E EBITDA) | E45: Next-12-month EBITDA at Dec-28 | F45: =$N$55 -> 20 | K45: Company | N45: GE Vernova Inc.
...

Sheet Reverse DCF
C2: GE Vernova (GEV)
C3: Reverse DCF: what the price needs, on consensus revenue
C4: US$ millions unless stated. Blue = input, black = formula, orange = assumption, grey = projection.
F6: Actual | H6: Projected quarters | S6: Fiscal year
C7: Fiscal period | E7: Note | F7: Q1'26A | G7: Q2'26A | H7: Q3'26E | I7: Q4'26E | J7: Q1'27E | K7: Q2'27E | L7: Q3'27E | M7: Q4'27E | N7: Q1'28E | O7: Q2'28E | P7: Q3'28E | Q7: Q4'28E | S7: FY2026E | T7: FY2027E | U7: FY2028E | V7: FY2029E
C8: Period end | F8: 46112 | G8: 46203 | H8: 46295 | I8: 46387 | J8: 46477 | K8: 46568 | L8: 46660 | M8: 46752 | N8: 46843 | O8: 46934 | P8: 47026 | Q8: 47118 | S8: 46387 | T8: 46752 | U8: 47118 | V8: 47483
C10: Cash flow (consensus, with the margin solved)
